Workbook

Sheet NL
A1: Planilha das NL
A2: Nº da NL | B2: Data da NL | C2: Histórico da NL | D2: Grupo de Despesa/FONTE
D3: ODC (IU 8) – NBA | E3: ODC (IU 0) – NDA | F3: ODC – NAA | G3: ODC – NAA | H3: INV. (IU 8) – NBA | I3: INV – NAA | J3: INV. - NAA
D4: '1000 / 3008 | E4: 1000 | F4: 1050 | G4: 3050 | H4: 1000 | I4: 1051 | J4: 1050
A5: 2025NL000481 | B5: 45742 | C5: LIM. ORC. (DECRETO N. 12.416, DE 21 DE MARCO DE 2025 ) FTE TESOURO | D5: =K5*D68 -> 38204321 | H5: =K5*H68 -> 2197573.1 | K5: 40401894
A6: 2025NL000593 | B6: 45742 | C6: LIM. ORC. (DECRETO N. 12.416, DE 21 DE MARCO DE 2025 ) FTE TESOURO INVESTIMENTO | D6: =K6*D68 -> 1313343.4 | H6: =K6*H68 -> 75545.593 | K6: 1388889
A7: 2025NL000793 | B7: 45742 | C7: LIM. ORC. (DECRETO N. 12.416, DE 21 DE MARCO DE 2025 ) FTE TESOURO CUSTEIO | E7: 11838003
A8: 2025NL000907 | B8: 45742 | C8: (44)LIM. ORC. (DECRETO N. 12.416, DE 21 DE MARÃ?O DE 2025) - FONTE 1050 | F8: =K8*F68 -> 19303829 | J8: =K8*J68 -> 5154049.7 | K8: 24457878
A9: 2025NL001105 | B9: 45749 | C9: (42)LIM. ORC. (DECRETO N. 12.416, DE 21 DE MARCO DE 2025) - FONTE 1050 | F9: =K9*F68 -> 2002085.6 | J9: =K9*J68 -> 534549.33 | K9: 2536634.9
A10: 2025NL001242 | B10: 45756 | C10: (41)LIM. ORC. (DECRETO N. 12.416, DE 21 DE MARCO DE 2025) - FONTE 1050 | F10: =K10*F68 -> 484702.22 | J10: =K10*J68 -> 129413.67 | K10: 614115.89
A11: 2025NL001363 | B11: 45763 | C11: (38)LIM. ORC. (DECRETO N. 12.416, DE 21 DE MARCO DE 2025) - FONTE 1050 | F11: =K11*F68 -> 1800710.6 | J11: =K11*J68 -> 480782.97 | K11: 2281493.6
A12: 2025NL001477 | B12: 45770 | C12: (41)LIM. ORC. (DECRETO N. 12.416, DE 21 DE MARCO DE 2025) - FONTE 1050 | F12: =K12*F68 -> 1775932.2 | J12: =K12*J68 -> 474167.23 | K12: 2250099.4
A13: 2025NL001577 | B13: 45771 | C13: LIM. ORC. (DECRETO N. 12.416, DE 12 DE MARCO DE 2025 ) FTE TESOURO CUSTEIO - ASSIST. ESTUDANTIL | E13: 5878207
A14: 2025NL001777 | B14: 45777 | C14: (42)LIM. ORC. (DECRETO N. 12.416, DE 21 DE MARCO DE 2025) - FONTE 1050 | F14: =K14*F68 -> 110580.16 | J14: =K14*J68 -> 29524.488 | K14: 140104.65
A15: 2025NL001885 | B15: 45782 | C15: LIM. ORC. (DECRETO N. 12.448, DE 30 DE ABRIL DE 2025 ) FTE TESOURO CUSTEIO | D15: =K15*D68 -> -1406262.3 | H15: =K15*H68 -> -80890.436 | K15: -1487152.8
A16: 2025NL001838 | B16: 45782 | C16: LIM. ORC. (DECRETO N. 12.448, DE 30 DE ABRIL DE 2025 ) FTE TESOURO CUSTEIO | E16: -12702583
A17: 2025NL002085 | B17: 45784 | C17: (42)LIM. ORC. (DECRETO N. 12.448, DE 30 DE ABRIL DE 2025) - FONTE 1050 | F17: =K17*F68 -> 1468712.6 | J17: =K17*J68 -> 392140.74 | K17: 1860853.3
A18: 2025NL002461 | B18: 45791 | C18: (41)LIM. ORC. (DECRETO NÂº 12.448, DE 30 DE ABRIL DE 2025) - FONTE 1050 | F18: =K18*$F$68 -> 499518.13 | J18: =K18*$J$68 -> 133369.46 | K18: 632887.59
A19: 2025NL002631 | B19: 21Mai25 | C19: (42)LIM. ORC. (DECRETO NÂº 12.448, DE 30 DE ABRIL DE 2025) - FONTE 1050 | F19: =K19*$F$68 -> 1986592 | J19: =K19*$J$68 -> 530412.6 | K19: 2517004.6
A20: 2025NL002803 | B20: 45805 | C20: (42)LIM. ORC. (DECRETO NÂº 12.448, DE 30 DE ABRIL DE 2025) - FONTE 1050 | F20: =K20*$F$68 -> 86481.859 | J20: =K20*$J$68 -> 23090.331 | K20: 109572.19
A21: 2025NL002300 | B21: 45789 | C21: LIM. ORC. (DECRETO N. 12.448, DE 30 DE ABRIL DE 2025 ) FTE TESOURO CUSTEIO | D21: =K21*$D$68 -> 1406262.3 | H21: =K21*$H$68 -> 80890.436 | K21: 1487152.8
A22: 2025NL002530 | B22: 45792 | C22: LIM. ORC. (DECRETO N. 12.416, DE 21 DE MARCO DE 2025 ) FTE TESOURO AJUSTE DE LIMITE | D22: =K22*$D$68 -> 1891214.4 | H22: =K22*$H$68 -> 108785.65 | K22: 2000000
A23: 2025NL002192 | B23: 45789 | C23: LIM. ORC. (DECRETO N. 12.416, DE 12 DE MARCO DE 2025 ) FTE TESOURO CUSTEIO | E23: 12702583
A24: 2025NL002529 | B24: 45792 | C24: LIM. ORC. (DECRETO N. 12.416, DE 21 DE MARCO DE 2025 ) FTE TESOURO AJUSTE DE LIMITE | E24: -2000000
A25: 2025NL002927 | B25: 45810 | C25: LIM. ORC. (DECRETO N. 12.477, DE 30 DE MAIO DE 2025 ) FTE TESOURO | D25: =K25*D68 -> 40222131 | E25: 4548257 | H25: =K25*H68 -> 2313640.7 | K25: 42535772
A26: 2025NL003177 | B26: 45812 | C26: (42)LIM. ORC. (DECRETO NÂº 12.448, DE 30 DE ABRIL DE 2025) - FONTE 1050 | F26: =K26*F68 -> 1542404.8 | J26: =K26*J68 -> 411816.29 | K26: 1954221.1
A27: 2025NL003387 | B27: 45819 | C27: (42)LIM. ORC. (DECRETO NÂº 12.448, DE 30 DE ABRIL DE 2025) - FONTE 1050 | F27: =K27*F68 -> 436252.9 | J27: =K27*J68 -> 116477.88 | K27: 552730.78
A28: 2025NL003781 | B28: 45835 | C28: LIM. ORC. (DECRETO N. 12.477, DE 30 DE MAIO DE 2025 ) FTE TESOURO | D28: =K28*D68 -> 13605168 | H28: =K28*H68 -> 782590.83 | K28: 14387759
A29: 2025NL004001 | B29: 45835 | C29: LIM. ORC. (DECRETO N. 12.477, DE 30 DE MAIO DE 2025 ) FTE TESOURO RECOMP PLOA | D29: =K29 -> 20516.42 | H29: =K29*H68 -> 1115.946 | K29: 20516.42
A30: 2025NL003537 | B30: 45826 | C30: (42)LIM. ORC. (DECRETO NÂº 12.448, DE 30 DE ABRIL DE 2025) - FONTE 1050 | F30: =K30*F68 -> 1824550.4 | J30: =K30*J68 -> 487148.1 | K30: 2311698.5
A31: 2025NL003665 | B31: 45833 | C31: (41)LIM. ORC. (DECRETO NÂº 12.448, DE 30 DE ABRIL DE 2025) - FONTE 1050 | F31: =K31*F68 -> 465734.75 | J31: =K31*J68 -> 124349.43 | K31: 590084.18
A32: 2025NL003892 | B32: 45835 | C32: (41)LIM. ORC. (DECRETO NÂº 12.448, DE 30 DE ABRIL DE 2025) - FONTE 1050 | E32: 3377411.2
A33: 2025NL004421 | B33: 45840 | C33: (41)LIM. ORC. (DECRETO NÂº 12.448, DE 30 DE ABRIL DE 2025) - FONTE 1050 | F33: =K33*F68 -> 1981561.9 | J33: =K33*J68 -> 529069.59 | K33: 2510631.5
A34: 2025NL004320 | B34: 45840 | C34: (100)LIM. ORC. (DECRETO NÂº 12.448, DE 30 DE ABRIL DE 2025) - FONTE 1051 | I34: 538270
A35: 2025NL004421 | B35: 45847 | C35: (41)LIM. ORC. (DECRETO NÂº 12.448, DE 30 DE ABRIL DE 2025) - FONTE 1050 | F35: =K35*F68 -> 518392.8 | J35: =K35*J68 -> 138408.93 | K35: 656801.73
A36: 2025NL004564 | B36: 45854 | C36: (41)LIM. ORC. (DECRETO N. 12.448, DE 30 DE ABRIL DE 2025) - FONTE 1050 | F36: =K36*F68 -> 1378671.5 | J36: =K36*J68 -> 368100.12 | K36: 1746771.7
A37: 2025NL004734 | B37: 45861 | C37: (43)LIM. ORC. (DECRETO N. 12.448, DE 30 DE ABRIL DE 2025) - FONTE 1050 | F37: =K37*F68 -> 476910.78 | J37: =K37*J68 -> 127333.39 | K37: 604244.17
A38: 2025NL005346 | B38: 45868 | C38: (41)LIM. ORC. (DECRETO N. 12.448, DE 30 DE ABRIL DE 2025) - FONTE 1050 | F38: =K38*F68 -> 311352.34 | J38: =K38*J68 -> 83129.904 | K38: 394482.24
A39: 2025NL005553 | B39: 45869 | C39: LIM. ORC. (DECRETO N. 12.566, DE 30 DE JULHO DE 2025 ) FTE TESOURO | D39: =K39*D68 -> 13607940 | H39: =K39*H68 -> 782750.25 | K39: 14390690
A40: 2025NL005444 | B40: 45869 | C40: LIM. ORC. (DECRETO N. 12.566, DE 30 DE JULHO DE 2025 ) FTE TESOURO | E40: 3377411.2
...

Sheet UO_26271
B3: UO 26271 - Execução dos Limites Liberados (Decreto nº 12.416 de 21 de março de 2025)
B6: Atualizado: 20/10/2025 | J6: =I6*12 -> 0
B7: TOTAL FONTE TESOURO + PRÓPRIAS | C7: =C9+C28 -> 214628958 | D7: =D9+D28 -> 233958183 | E7: =E9+E28 -> 0 | F7: =F9+F28 -> 2.5742673e+08 | G7: =G9+G28 -> 61976502 | H7: =H9+H28 -> 2.5620914e+08 | I7: =I9+I28 -> 1.897026 | J7: =J9+J28 -> 1.8583912e+08 | K7: =K9+K28 -> 37495264
B8: FONTE TESOURO | C8: DOTAÇÃO INICIAL 2025 (sem emendas) | D8: DOTAÇÃO ATUALIZADA 2025 (sem emendas) | E8: LIMITE RETIDO | F8: LIMITE LIBERADO 2024 | G8: LIBERAÇÃO LIMITE EXTRA | H8: TOTAL LIMITE LIBERADO | I8: % LIMITE LIBERADO (Total Lim. Lib./Dot Inic.) | J8: EMPENHADO | K8: A EMPENHAR | N8: Indicador TCU (Dotação Inicial/Limite recebido)
B9: TOTAL (CUSTEIO+INVESTIMENTO) | C9: =C10+C20 -> 213182043 | D9: =D10+D20 -> 213217214 | E9: =E10+E20 -> 0 | F9: =F10+F20 -> 1.9545023e+08 | G9: =G10+G20 -> 0 | H9: =H10+H20 -> 1.9545023e+08 | I9: =H9/D9 -> 0.9166719 | J9: =J10+J20 -> 1.8583912e+08 | K9: =D9-J9 -> 27378091 | N9: Tesouro | O9: =C7/F7 -> 0.83374775
B10: CUSTEIO | C10: =SUM(C11:C19) -> 198789040 | D10: =SUM(D11:D19) -> 203824211 | E10: =SUM(E11:E17) -> 0 | F10: =F11+F13 -> 1.8683998e+08 | G10: =SUM(G11:G17) -> 0 | H10: =H11+H13 -> 1.8683998e+08 | I10: =H10/D10 -> 0.91667214 | J10: =SUM(J11:J19) -> 1.834836e+08 | K10: =D10-J10 -> 20340614 | N10: Próprios | O10: =C29/H29 -> 0.024026893
B11: Assistência Estudantil – 4002 | C11: =SUM(Z139:Z142) -> 40235215 | D11: =SUM(AA139:AA142) -> 40235215 | E11: 0 | F11: =NL!E66 -> 37151523 | H11: =F11+G11 -> 37151523 | I11: =H11/(D11+D12) -> 0.91666667 | J11: =SUM(AB139:AB142) -> 36791928 | K11: =D11-J11 -> 3443287.1
B12: Anuidades – 00PW e 00UU | C12: =SUM(Z95:Z128) -> 293719 | D12: =SUM(AA95:AA128) -> 293719 | J12: =SUM(AB95:AB128) -> 88886.7 | K12: =D12-J12 -> 204832.3 | L12: =D12/12 -> 24476.583
B13: Funcionamento – 20RK | C13: =SUM(Z132) -> 153807483 | D13: =SUM(AA132) -> 158842654 | E13: 0 | F13: =NL!D66 -> 1.4968845e+08 | H13: =F13+G13 -> 1.4968845e+08 | I13: =H13/SUM(D13:D19) -> 0.9166735 | J13: =SUM(AB132) -> 1.4334438e+08 | K13: =D13-J13 -> 15498276 | L13: =L12*11 -> 269242.42
B14: HVET – 20RK | C14: =SUM(Z135) -> 484811 | D14: =SUM(AA135) -> 484811 | J14: =SUM(AB135) -> 464965.24 | K14: =D14-J14 -> 19845.76 | L14: =L13-J12 -> 180355.72 | M14: =7202095.87-L14 -> 7021740.2
B15: Reestruturação e Modernização – 8282 (Museus) | C15: =SUM(Z144) -> 52100 | D15: =SUM(AA144) -> 52100 | J15: =SUM(AB144) -> 0 | K15: =D15-J15 -> 52100
B16: Fomento – 20GK | C16: =SUM(Z129:Z131) -> 2321331 | D16: =SUM(AA129:AA131) -> 2321331 | J16: =SUM(AB129:AB131) -> 1959831 | K16: =D16-J16 -> 361500
B17: Capacitação – 4572 | C17: =SUM(Z143) -> 1083763 | D17: =SUM(AA143) -> 1083763 | J17: =SUM(AB143) -> 516512.68 | K17: =D17-J17 -> 567250.32
B18: Internacionalização – 21GS | C18: =SUM(Z137:Z138) -> 418416 | D18: =SUM(AA137:AA138) -> 418416 | J18: =SUM(AB137:AB138) -> 317095.81 | K18: =D18-J18 -> 101320.19
B19: Educação à Distância – 21D7 | C19: =SUM(Z136) -> 92202 | D19: =SUM(AA136) -> 92202 | J19: =SUM(AB136) -> 0 | K19: =D19-J19 -> 92202
B20: INVESTIMENTO | C20: =SUM(C21:C22) -> 14393003 | D20: =SUM(D21:D22) -> 9393003 | E20: =SUM(E21:E22) -> 0 | F20: =SUM(F21:F22) -> 8610252.7 | G20: =SUM(G21:G22) -> 0 | H20: =SUM(H21:H22) -> 8610252.7 | I20: =I21 -> 0.91666667 | J20: =SUM(J21:J22) -> 2355526 | K20: =SUM(K21:K22) -> 7037477
B21: Funcionamento – 20RK | C21: =Z90 -> 14393003 | D21: =AA90 -> 9393003 | E21: 0 | F21: =NL!H66 -> 8610252.7 | G21: 0 | H21: =F21+G21 -> 8610252.7 | I21: =H21/SUM(D21:D22) -> 0.91666667 | J21: =SUM(AB90) -> 2355526 | K21: =D21-J21 -> 7037477
B22: Reestruturação – 8282 | C22: 0 | D22: 0 | J22: =SUM(AB94) -> 0 | K22: =D22-J22 -> 0
B27: RECEITA PRÓPRIA - DEPENDE DE ARRECADAÇÃO | C27: DOTAÇÃO INICIAL 2025 (sem emendas) | D27: DOTAÇÃO ATUALIZADA 2025 (sem emendas) | E27: LIMITE RETIDO | F27: ARRECADAÇÃO (1050) | G27: LIMITE AUTORIZADO 2024 | H27: LIMITE LIBERADO 2024 | I27: % LIMITE LIBERADO (Total Lim. Lib./Arrecadação) | J27: EMPENHADO | K27: A EMPENHAR
B28: TOTAL (1050+1051+3050+3051) | C28: =C29+C33+C35 -> 1446915 | D28: =D29+D33+D35 -> 20740969 | E28: =E29+E33+E35 -> 0 | F28: =F29+F33+F35 -> 61976502 | G28: =G29+G33+G35 -> 61976502 | H28: =H29+H33 -> 60758916 | I28: =H28/F28 -> 0.98035407 | J28: =J29+J33 -> 0 | K28: =K29+K33 -> 10117173
B29: TOTAL PRÓPRIOS – fonte 1050 | C29: =SUM(C30:C32) -> 1446915 | D29: =SUM(D30:D32) -> 10655443 | E29: =SUM(E30:E32) -> 0 | F29: =SUM(F30:F32) -> 61438232 | G29: =SUM(G30:G32) -> 61438232 | H29: =SUM(H30:H32) -> 60220646 | I29: =H29/F29 -> 0.98018195 | J29: =SUM(J30:J32) -> 0 | K29: =SUM(K30:K32) -> 10117173
B30: CUSTEIO (fonte 1050) - 20RK | C30: =SUM(Z134) -> 0 | D30: =SUM(AA134) -> 10067173 | E30: 0 | F30: =SUM(Receitas!O5:O18) -> 61438232 | G30: =F30 -> 61438232 | H30: =NL!F66+NL!J66 -> 60220646 | I30: =H30/F30 -> 0.98018195 | J30: =SUM(AB134) -> 0 | K30: =D30-J30 -> 10067173
B31: INVESTIMENTO (fonte 1050) - 20RK | C31: =Z92 -> 1396915 | D31: =AA92 -> 538270 | J31: =AB92 -> 0 | K31: =AC92 -> 0
B32: INVESTIMENTO (fonte 1050) - 8282 | C32: =SUM(Z94) -> 50000 | D32: =SUM(AA94) -> 50000 | J32: =SUM(AB94) -> 0 | K32: =D32-J32 -> 50000
B33: TOTAL PRÓPRIOS – fonte 1051 | C33: =C34 -> 0 | D33: =D34 -> 18353 | E33: =E34 -> 0 | F33: =F34 -> 538270 | G33: =G34 -> 538270 | H33: =H34 -> 538270 | I33: =H33/F33 -> 1 | J33: =J34 -> 0
B34: INVESTIMENTO (fonte 1051) - 20RK | C34: =SUM(Z93) -> 0 | D34: =SUM(AA93) -> 18353 | E34: 0 | F34: =Receitas!O19 -> 538270 | G34: =F34 -> 538270 | H34: =NL!I66 -> 538270 | I34: =H34/F34 -> 1 | J34: =SUM(AB93) -> 0 | K34: =D34-J34 -> 18353
B35: TOTAL PRÓPRIOS – fonte 3050 e 3051 (SUPERÁVIT) | C35: =C36 -> 0 | D35: =D36 -> 10067173 | E35: =E36 -> 0 | F35: =F36 -> 0 | G35: =G36 -> 0 | H35: =H36 -> - | I35: =H35/F35 -> #VALUE! | J35: =J36 -> 0
B36: Custeio (fonte 3050) - 20RK | C36: =Z134 -> 0 | D36: =AA134 -> 10067173 | E36: 0 | F36: =Receitas!O21 -> 0 | G36: =F36 -> 0 | H36: - | I36: =H36/F36 -> #VALUE! | J36: =SUM(AB95) -> 0 | K36: =D36-J36 -> 10067173
B37: Investimento (fonte 3051) - 20RK | C37: =Z93 -> 0 | D37: =AA93 -> 18353 | E37: 0 | F37: =Receitas!O22 -> 0 | G37: =F37 -> 0 | H37: =NL!I69 -> 0 | I37: =H37/F37 -> #DIV/0! | J37: =SUM(AB96) -> 0 | K37: =D37-J37 -> 18353
F39: 58738456
H40: Tesouro (IU 0-4002 e Anuidades) | I40: Tesouro (IU 8)* | J40: Próprios | K40: DRU
G41: Limite Disponível | H41: =H11-SUM(J11:J12) -> 270708.23 | I41: =H13+H20-SUM(J13:J19)-J20 -> 9340397.1 | J41: =H28-J28 -> 60758916 | K41: =8725941.34+2152152.02+16333.73+2745.09+774677.75+254192.52 -> 11926042
G42: Total | H42: =H41+I41+J41 -> 70370021
G43: Conta Limite Orçamentário a Utilizar: 823200100
B46: EMENDAS | C46: DOTAÇÃO INICIAL 2025 | D46: DOTAÇÃO ATUALIZADA 2025 | E46: CRÉDITO BLOQUEADO | F46: LIMITE LIBERADO 2024 | G46: EMPENHADO 2024 | H46: PAGO 2024 | I46: 15071740 | K46: Crédito Livre custeio 1050
B47: TOTAL | C47: =C48+C52 -> 65080888 | D47: =D48+D52 -> 74850888 | E47: =E48+E52 -> 6736334 | F47: =F48+F52 -> 33325419 | G47: =G48+G52 -> 7841555.7 | H47: =H48+H52 -> 1373041 | K47: 8711534.4
B48: CUSTEIO | C48: =SUM(C49:C51) -> 32166888 | D48: =SUM(D49:D51) -> 44606401 | E48: =SUM(E49:E51) -> 2500001 | F48: =SUM(F49:F51) -> 21313692 | G48: =SUM(G49:G51) -> 7328157.5 | H48: =SUM(H49:H51) -> 1373041
B49: RP 2 - Despesa Discricionária - Emenda de Bancada | F49: 0 | K49: Crédito Livre custeio 1000
B50: RP 6 - Discricionária e decorrente de Emenda Individual | C50: =Z146+Z147 -> 1950001 | D50: =AA146+AA147 -> 4220001 | E50: 1 | F50: 1950000 | G50: =AB146+AB147 -> 532712.64 | H50: =AC146+AC147 -> 0 | K50: =44565589.98+9796183.09 -> 54361773
B51: RP 7 - Despesa Discricionária - Emenda de Bancada | C51: =Z150 -> 30216887 | D51: =AA150 -> 40386400 | E51: 2500000 | F51: =15117969+4245723 -> 19363692 | G51: =AB150 -> 6795444.8 | H51: =AC150 -> 1373041
...

Sheet Receitas
A1: Receita Realizada da UnB | T1: 4
A2: =UO_26271!B6 -> Atualizado: 20/10/2025
A3: Unidade Orçamentária | B3: Fonte SOF | C3: Item Informação | E3: RECEITA ORCAMENTARIA (LIQUIDA) | F3: RECEITA ORCAMENTARIA (LIQUIDA) | G3: RECEITA ORCAMENTARIA (LIQUIDA) | H3: RECEITA ORCAMENTARIA (LIQUIDA) | I3: RECEITA ORCAMENTARIA (LIQUIDA) | J3: RECEITA ORCAMENTARIA (LIQUIDA) | K3: RECEITA ORCAMENTARIA (LIQUIDA) | L3: RECEITA ORCAMENTARIA (LIQUIDA) | M3: RECEITA ORCAMENTARIA (LIQUIDA) | N3: RECEITA ORCAMENTARIA (LIQUIDA) | O3: Total | P3: Total receita (fev - jul + set) | Q3: Média | R3: Estimativa de Total anual (média)
C4: Natureza Receita | E4: JAN/2025 | F4: FEV/2025 | G4: MAR/2025 | H4: 45748 | I4: 45778 | J4: 45809 | K4: 45839 | L4: 45870 | M4: 45901 | N4: 45931
A5: 26271 | B5: 1050 | C5: 13110111 | D5: ALUGUEIS E ARRENDAMENTOS-PRINCIPAL | E5: 4507417.2 | F5: 3271619.4 | G5: 3102071.4 | H5: 3610312.1 | I5: 3122817.8 | J5: 3132812.9 | K5: 3128487.3 | L5: 909371.33 | M5: 3089481.3 | N5: 1688906.6 | O5: =SUM(E5:N5) -> 29563297 | P5: =SUM(F5:K5)+M5 -> 22457602 | Q5: =P5/7 -> 3208228.9 | R5: =Q5*12 -> 38498747
C6: 13110112 | D6: ALUGUEIS E ARRENDAMENTOS-MULTAS E JUROS | E6: 6782 | F6: 5590.38 | G6: 5902.78 | H6: 5761.22 | I6: 5487.27 | J6: 6712.04 | K6: 5697.69 | L6: 2383.8 | M6: 7471.07 | N6: 5412.03 | O6: =SUM(E6:N6) -> 57200.28 | P6: =SUM(F6:K6)+M6 -> 42622.45 | Q6: =P6/7 -> 6088.9214 | R6: =Q6*12 -> 73067.057
C7: 13210101 | D7: REMUNERACAO DE DEPOSITOS BANCARIOS-PRINCIPAL | E7: 38997.15 | F7: 42125.58 | G7: 49916.99 | H7: 44316.98 | I7: 43149.15 | J7: 45413.58 | K7: 41943.55 | L7: 48448.51 | M7: 41848.03 | N7: 29728.8 | O7: =SUM(E7:N7) -> 425888.32 | P7: =SUM(F7:K7)+M7 -> 308713.86 | Q7: =P7/7 -> 44101.98 | R7: =Q7*12 -> 529223.76
C8: 13999901 | D8: OUTRAS RECEITAS PATRIMONIAIS-PRINCIPAL | E8: 422068.37 | F8: 292530.28 | G8: 295538.11 | H8: 298167.78 | I8: 305680.45 | J8: 304776.01 | K8: 310888.86 | L8: 53832.58 | M8: 310410.76 | O8: =SUM(E8:N8) -> 2593893.2 | P8: =SUM(F8:K8)+M8 -> 2117992.2 | Q8: =P8/7 -> 302570.32 | R8: =Q8*12 -> 3630843.9
C9: 14110101 | D9: RECEITA AGROPECUARIA-PRINCIPAL | F9: 31053.75 | J9: 31370.15 | K9: 90198.45 | L9: 142943.6 | M9: 45601.8 | N9: 10629.6 | O9: =SUM(E9:N9) -> 351797.35 | P9: =SUM(F9:K9)+M9 -> 198224.15 | Q9: =P9/7 -> 28317.736 | R9: =Q9*12 -> 339812.83
C10: 16110101 | D10: SERV.ADMINISTRAT.E COMERCIAIS GERAIS-PRINC. | E10: 9806918.1 | F10: 1575534.8 | G10: 3115206.4 | H10: 2781284.9 | I10: 1669985.8 | J10: 2277080.9 | K10: 1182395.6 | L10: 1994467.8 | M10: 1150101.1 | N10: 1031764.8 | O10: =SUM(E10:N10) -> 26584740 | P10: =SUM(F10:K10)+M10 -> 13751590 | Q10: =P10/7 -> 1964512.8 | R10: =(Q10*12)+Q24 -> 31416559
C11: 16110102 | D11: SERV.ADMINISTRAT.E COMERCIAIS GERAIS-MUL.JUR. | E11: 17.2 | F11: 458.5 | G11: 258.4 | H11: 452 | I11: 204.5 | J11: 325.59 | K11: 3.6 | L11: 707 | M11: 491.65 | N11: 4.5 | O11: =SUM(E11:N11) -> 2922.94 | P11: =SUM(F11:K11)+M11 -> 2194.24 | Q11: =P11/7 -> 313.46286 | R11: =Q11*12 -> 3761.5543
C12: 16110201 | D12: INSCR.EM CONCURSOS E PROC.SELETIVOS-PRINCIPAL | E12: 20102.4 | F12: 14712.6 | G12: 2142.4 | H12: 100 | I12: 9916 | J12: 9558 | K12: 1450 | L12: 810 | M12: 440 | N12: 2813.6 | O12: =SUM(E12:N12) -> 62045 | P12: =SUM(F12:K12)+M12 -> 38319 | Q12: =P12/7 -> 5474.1429 | R12: =Q12*12 -> 65689.714
C13: 16999901 | D13: OUTROS SERVICOS-PRINCIPAL | E13: 11.7 | F13: 79 | G13: 11.7 | J13: 50 | L13: 531 | O13: =SUM(E13:N13) -> 683.4 | P13: =SUM(F13:K13)+M13 -> 140.7 | Q13: =P13/7 -> 20.1 | R13: =Q13*12 -> 241.2
C14: 19110901 | D14: MULTAS E JUROS PREVISTOS EM CONTRATOS-PRINC. | E14: 341.4 | F14: 9186.01 | G14: 12526.43 | H14: 4963.26 | I14: 11564.11 | J14: 12380.78 | K14: 12745.37 | L14: 11275.47 | M14: 5640.85 | N14: 13590.27 | O14: =SUM(E14:N14) -> 94213.95 | P14: =SUM(F14:K14)+M14 -> 69006.81 | Q14: =P14/7 -> 9858.1157 | R14: =Q14*12 -> 118297.39
C15: 19110902 | D15: MULTAS E JUROS PREVISTOS EM CONTRATOS-MUL.JUR | N15: 9.49 | O15: =SUM(E15:N15) -> 9.49 | P15: =SUM(F15:K15)+M15 -> 0 | Q15: =P15/7 -> 0 | R15: =Q15*12 -> 0
C16: 19220631 | D16: RESTIT.DESP.PRIMARIAS EX.ANTERIORES-PRINC. | J16: 380 | O16: =SUM(E16:N16) -> 380 | P16: =SUM(F16:K16)+M16 -> 380 | Q16: =P16/7 -> 54.285714 | R16: =Q16*12 -> 651.42857
C17: 19229901 | D17: OUTRAS RESTITUICOES-PRINCIPAL | E17: -9846.9 | F17: 73461.32 | G17: 351691.69 | H17: 245089.34 | I17: 152858.12 | J17: 181259.01 | K17: 508211.75 | L17: 52854.8 | M17: 46857.73 | N17: 98663.58 | O17: =SUM(E17:N17) -> 1701100.4 | P17: =SUM(F17:K17)+M17 -> 1559429 | Q17: =P17/7 -> 222775.57 | R17: =Q17*12 -> 2673306.8
C18: 76110201 | D18: INSC.CONCURSOS E PROC.SELETIVOS-PRINC.-INTRA | G18: 60 | O18: =SUM(E18:N18) -> 60 | P18: =SUM(F18:K18)+M18 -> 60 | Q18: =P18/7 -> 8.5714286 | R18: =Q18*12 -> 102.85714
B19: 1051 | C19: 22130101 | D19: ALIENACAO DE BENS MOVEIS E SEMOVENTES-PRINC. | J19: 538270 | N19: 0 | O19: =SUM(E19:N19) -> 538270 | P19: =SUM(F19:K19)+M19 -> 538270 | Q19: =P19/7 -> 76895.714 | R19: =Q19*12 -> 922748.57
A20: Total | E20: =SUM(E5:E19) -> 14792809 | F20: =SUM(F5:F19) -> 5316351.7 | G20: =SUM(G5:G19) -> 6935326.3 | H20: =SUM(H5:H19) -> 6990447.6 | I20: =SUM(I5:I19) -> 5321663.3 | J20: =SUM(J5:J19) -> 6540389 | K20: =SUM(K5:K19) -> 5282022.2 | L20: =SUM(L5:L19) -> 3217625.9 | ... R20: =SUM(R5:R19) -> 78273053
A21: Fonte: Tesouro Gerencial.
A22: Conta Contábil: 899910802
J23: Mês exceto 1051 | K23: =(SUM(E5:K18)/7)*12 -> 86812695
J24: LOA | K24: 77856818 | Q24: =E10-Q10 -> 7842405.3
H25: receitas cebraspe | K25: =K23-K24 -> 8955876.8
H26: 8765876.4
H27: 1174337 | M27: 1149
H28: 2209000.7 | M28: 904
H29: 1913213.7 | M29: 20.7
H30: 1276164.6 | M30: 400
H31: 1188864 | M31: 170
H32: 209635.95 | I32: =SUM(H27:H31)/5 -> 1552316 | M32: =-8279.23 -> -8279.23
H33: previsão 2 semestre | M33: 405
H34: 7655247.2 | M34: 2862
M35: 50
M36: 452
M37: 3144
M38: 220
M39: 1585
M40: 452
...
