Workbook
Name _xlcn.WorksheetConnection_II.SituaçãoAtualA2AA90: 'Estudo de Crédito'!$A$3:$P$29
Name _xlcn.WorksheetConnection_II.SituaçãoAtualA2AA90: 'Prog 03.06'!$A$3:$F$38
Name _xlcn.WorksheetConnection_II.SituaçãoAtualA2AA90: 'Prog 07.04'!$A$3:$P$25
Name _xlcn.WorksheetConnection_II.SituaçãoAtualA2AA90: 'Prog-08.07'!$A$3:$P$35
Name _xlcn.WorksheetConnection_II.SituaçãoAtualA2AA90: 'Prog-09.10'!$A$3:$F$30
Name _xlcn.WorksheetConnection_II.SituaçãoAtualA2AA90: 'Prog-12.03'!$B$3:$G$18
Name _xlcn.WorksheetConnection_II.SituaçãoAtualA2AA90: 'Prog-16.09'!$A$3:$L$14
Name _xlcn.WorksheetConnection_II.SituaçãoAtualA2AA90: 'Prog-17.03 PRC'!$B$3:$G$6
Name _xlcn.WorksheetConnection_II.SituaçãoAtualA2AA90: 'Prog-18.08'!$A$3:$E$38
Name _xlcn.WorksheetConnection_II.SituaçãoAtualA2AA90: 'Prog-25.02'!$A$3:$P$46
Name _xlcn.WorksheetConnection_II.SituaçãoAtualA2AA90: 'Programação 17.11'!$A$3:$O$35
Name _xlcn.WorksheetConnection_II.SituaçãoAtualA2AA90: 'Variáveis fixas'!$A$1:$L$89
Name _xlcn.WorksheetConnection_II.SituaçãoAtualA2AA90: 'I. Situação Atual'!$A$3:$O$91
Name _xlcn.WorksheetConnection_II.SituaçãoAtualA2AA93: 'Estudo de Crédito'!$A$3:$P$29
Name _xlcn.WorksheetConnection_II.SituaçãoAtualA2AA93: 'Prog 03.06'!$A$3:$F$38
Name _xlcn.WorksheetConnection_II.SituaçãoAtualA2AA93: 'Prog 07.04'!$A$3:$P$25
Name _xlcn.WorksheetConnection_II.SituaçãoAtualA2AA93: 'Prog-08.07'!$A$3:$P$35
Name _xlcn.WorksheetConnection_II.SituaçãoAtualA2AA93: 'Prog-09.10'!$A$3:$F$30
Name _xlcn.WorksheetConnection_II.SituaçãoAtualA2AA93: 'Prog-12.03'!$B$3:$G$18
Name _xlcn.WorksheetConnection_II.SituaçãoAtualA2AA93: 'Prog-16.09'!$A$3:$L$14
Name _xlcn.WorksheetConnection_II.SituaçãoAtualA2AA93: 'Prog-17.03 PRC'!$B$3:$G$6
Name _xlcn.WorksheetConnection_II.SituaçãoAtualA2AA93: 'Prog-18.08'!$A$3:$E$38
Name _xlcn.WorksheetConnection_II.SituaçãoAtualA2AA93: 'Prog-25.02'!$A$3:$P$46
Name _xlcn.WorksheetConnection_II.SituaçãoAtualA2AA93: 'Programação 17.11'!$A$3:$O$35
Name _xlcn.WorksheetConnection_II.SituaçãoAtualA2AA93: 'Variáveis fixas'!$A$1:$L$89
Name _xlcn.WorksheetConnection_II.SituaçãoAtualA2AA93: 'I. Situação Atual'!$A$3:$O$91
Name Área_impressão_IM: [1]FLUXO98!$A$1:$N$68
Name PRINT_AREA_MI: [1]FLUXO98!$A$1:$N$69
Name SegmentaçãodeDados_Classificação: #N/A
Name SegmentaçãodeDados_Classificação1: #N/A
Name SegmentaçãodeDados_Descrição_das_despesas: #N/A
Name SegmentaçãodeDados_Descrição_das_despesas1: #N/A

Sheet I. Situação Atual
A1: Acompanhamento de Contratos* | AA1: continuados | AB1: =AB4+AB5+AB6+AB7+AB10+AB11+AB14+AB17+SUM(AB37:AB48)+AB52+AB55+AB56+AB58+AB81+AB83 -> 6498237.3 | AC1: spi | AE1: ver observação | AH1: =SUM(AB59:AB70) -> 350001.99
A2: Data de Atualização: 10/11/2025 | AB2: =AB7+AB14+AB17+AB37+AB38+AB39+AB41+AB43+AB44+AB45+AB46+AB47+AB48+AB52+AB55+AB56+AB58+AB81+AB83 -> 6487949.3 | AC2: por demanda | AE2: NÃO ANULAR | AH2: =AB10+AB11+AB12+AB18+AB23+AB24+AB25+AB26+AB27+#REF!+AB28+AB29+AB30+AB31+AB36+AB32+AB33+AB53+AB54+AB57+AB77+AB78+AB80+AB86+AB87+AB88+AB89+AB90+AB91 -> #REF!
A3: Descrição das despesas | B3: UGR | C3: PI 2025 | D3: CNPJ | E3: Processo | F3: Vigência | G3: Status do Contrato | H3: Situação da prorrogação | I3: nº Contrato | J3: Valor Contrato Média mensal | K3: Valor Cont Continuado Mensal | L3: Total estimado Anual | M3: Saldo Empenhos 2025 | N3: Saldo de Empenhos RAP | O3: Total RAP + Empenho | P3: 45658 | Q3: 45689 | R3: 45717 | S3: 45748 | T3: 45778 | U3: 45809 | V3: 45839 | W3: 45870 | X3: 45901 | Y3: 45931 | Z3: 45962 | AA3: 45992 | AB3: Total necessário | AC3: Causas Judiciais | AD3: OUT-NOV (2024) | AE3: Saldo passivel de Anulação | AF3: Necessidade de Empenho até Novembro | AG3: Necessidade Janeiro | AH3: =AB74+AB75+AB76 -> 0
A4: - Estagiários UnB (novo PI - estagiários) | B4: DGP/ folha | C4: VGM01N01N2N | J4: 161000 | L4: =J4*12 -> 1932000 | M4: 659623.24 | N4: 20575.19 | O4: =SUM(M4:N4) -> 680198.43 | AB4: =SUM(Y4:AA4) -> 0 | AC4: Energia e água | AD4: =SUM(J4:K4)*2 -> 322000 | AE4: =O4-AD4 -> 358198.43 | AG4: =(SUM(J4:K4)*2)-O4 -> -358198.43 | AH4: =AB8+AB9 -> 0
A5: Estagiários - auxílio transporte | B5: DGP/ folha | C5: VGM01N01N7N | J5: 36375 | M5: 216315.33 | N5: 7160.7 | O5: =SUM(M5:N5) -> 223476.03 | AB5: =SUM(Y5:AA5) -> 0 | AC5: Contratos MPE e Poli | AH5: =AB50+AB49+AB51 -> 5086454.7
A6: Pasep - HUB | B6: HUB | C6: VGM01N01N1N | J6: 49000 | L6: =48891*13.33 -> 651717.03 | M6: 90145.45 | O6: =SUM(M6:N6) -> 90145.45 | AA6: =J6*2-O6 -> 7854.55 | AB6: =SUM(Y6:AA6) -> 7854.55 | AC6: RU | AH6: =AB71 -> 1571668.7
A7: Pasep - UnB | B7: DGP/ folha | C7: VGM01N01N1N | J7: 810000 | L7: =J7*12 -> 9720000 | M7: 1492474.5 | N7: 0 | O7: =SUM(M7:N7) -> 1492474.5 | T7: =810000-556810 -> 253190 | U7: =J7 -> 810000 | V7: =J7 -> 810000 | AA7: =J7*2-O7 -> 127525.53 | AB7: =SUM(Y7:AA7) -> 127525.53 | AD7: =SUM(J7:K7)*2 -> 1620000 | AE7: =O7-AD7 -> -127525.53 | AG7: =(SUM(J7:K7)*2)-O7 -> 127525.53 | AH7: =AB2+AH1+AH2+AH3+AH4+AH5+AH6 -> #REF!
A8: '- Serviços de Energia Elétrica (PRC) – já com CI | C8: VGM01N01I2N | D8: 075522669/000192 | J8: 1361927.6 | L8: =J8*12 -> 16343131 | M8: =45872.52+983974.29 -> 1029846.8 | N8: =5031931.32+4476318.75 -> 9508250.1 | O8: =SUM(M8:N8) -> 10538097 | AB8: =SUM(Y8:AA8) -> 0
A9: - Serviços de Água e Esgoto (PRC) | B9: INFRA | C9: VGM01N01I3N | D9: 82024000137 | J9: 700000 | L9: =J9*12 -> 8400000 | M9: =257146.6+2437295.23 -> 2694441.8 | N9: =249401.4 -> 249401.4 | O9: =SUM(M9:N9) -> 2943843.2 | U9: =J9-354401 -> 345599 | AB9: =SUM(Y9:AA9) -> 0 | AD9: =SUM(J9:K9)*2 -> 1400000 | AE9: =O9-AD9 -> 1543843.2 | AF9: =O9-Y9-Z9 -> 2943843.2 | AG9: =(SUM(J9:K9)*2)-O9 -> -1543843.2
A10: SANEAGO - Água e esgoto UnB Cerrado (corrigir a média) | B10: UnB Cerrado | C10: VGM01N01I3N | D10: 01616929000102 | J10: 333 | L10: =J10*12 -> 3996 | M10: 999 | N10: 1332 | O10: =SUM(M10:N10) -> 2331 | W10: 333 | AB10: =SUM(Y10:AA10) -> 0 | AE10: =O10-AD10 -> 2331
A11: Energia Elétrica UnB Cerrado - CONTRATO CCER - ENEL N. 36/2020 e CELG DISTRIBUIÇÃO S.A - CELG D, Equatorial Goiás Distribuidora de Energia S/A | B11: UnB Cerrado | C11: VGM01N01I2N | D11: 1543032000104 | E11: 23106.044802/2020-09 23106.083937/2023-24 | I11: 36/2020 | J11: 1585.03 | L11: =J11*12 -> 19020.36 | M11: =570.63+124.47 -> 695.1 | N11: 41.48 | O11: =SUM(M11:N11) -> 736.58 | U11: =J11-324 -> 1261.03 | W11: =1585-1230 -> 355 | Z11: =J11-O11 -> 848.45 | AA11: =J11 -> 1585.03 | AB11: =SUM(Y11:AA11) -> 2433.48 | AD11: =SUM(J11:K11)*2 -> 3170.06 | AE11: =O11-AD11 -> -2433.48 | AG11: =(SUM(J11:K11)*2)-O11 -> 2433.48
A12: OI SA recuperação judicial | B12: STI | C12: VGM01N01I4N | D12: 76535764000143 | E12: 23106.012727/2018-94 | F12: 46247 | G12: =IF((F12-TODAY())<0,"EXPIRADO", IF((F12-TODAY())<=60,"EM BREVE","NO PRAZO")) -> NO PRAZO | I12: 515/2021 | J12: 60000 | L12: =J12*12 -> 720000 | M12: 105024.66 | N12: 0 | O12: =SUM(M12:N12) -> 105024.66 | R12: =J12 -> 60000 | S12: =J12 -> 60000 | T12: =J12 -> 60000 | AA12: =J12*2-O12 -> 14975.34 | AB12: =SUM(Y12:AA12) -> 14975.34 | AD12: =SUM(J12:K12)*2 -> 120000 | AE12: =O12-AD12 -> -14975.34 | AF12: =-Y12-Z12 -> 0 | AG12: =(SUM(J12:K12)*2)-O12 -> 14975.34
A13: Novo contrato (serviço de manutenção preventiva programada e corretiva da sala cofre instalada na STI/UnB) | B13: STI | C13: VGM01N01A2N | E13: 23106.020472/2024-81 | H13: Ultimo despacho DPO informa certificação orçamentária apenas, a licitação está correndo em outro SEI. | AB13: =SUM(Y13:AA13) -> 0 | AG13: =(SUM(J13:K13)*2)-O13 -> 0
A14: - Central IT - Suporte TI (Serviços de Manutenção dos Computadores da UnB) | B14: STI | C14: VGM01N01A3N | D14: 07171299000196 | E14: 23106.007549/2018-80 | F14: 45836 | G14: =IF((F14-TODAY())<0,"EXPIRADO", IF((F14-TODAY())<=60,"EM BREVE","NO PRAZO")) -> EXPIRADO | I14: 507/2019 | K14: =L14/12 -> 369702.92 | L14: =4436435.04 -> 4436435 | M14: 0 | N14: 0 | O14: =SUM(M14:N14) -> 0 | R14: =K14-O14 -> 369702.92 | AB14: =SUM(Y14:AA14) -> 0 | AD14: =SUM(J14:K14)*2 -> 739405.84 | AE14: =O14-AD14 -> -739405.84 | AG14: =(SUM(J14:K14)*2)-O14 -> 739405.84
A15: QUALIFICAR - Suporte TI (Serviços de Manutenção dos Computadores da UnB) | B15: STI | C15: VGM01N01A3N | D15: 04.752.792/0001-01 | E15: 23106.016945/2023-65 | F15: 46147 | G15: =IF((F15-TODAY())<0,"EXPIRADO", IF((F15-TODAY())<=60,"EM BREVE","NO PRAZO")) -> NO PRAZO | I15: 512/2025 | K15: =L15/12 -> 182288 | L15: 2187456 | M15: 323045.17 | N15: 0 | O15: =SUM(M15:N15) -> 323045.17 | U15: 182288 | AA15: =K15*2-O15 -> 41530.83 | AB15: =SUM(Y15:AA15) -> 41530.83 | AG15: =(SUM(J15:K15)*2)-O15 -> 41530.83
A16: - Rede Gigacandanga - Convênio FUB/ RNT | B16: STI | C16: VGM01N01K8N | D16: 30814920000104 | E16: 23106.032698/2019-68 23106.108762/2019-99 23106.027099/2024-90 | F16: 47457 | G16: =IF((F16-TODAY())<0,"EXPIRADO", IF((F16-TODAY())<=60,"EM BREVE","NO PRAZO")) -> NO PRAZO | L16: 752926 | N16: 0 | O16: =SUM(M16:N16) -> 0 | AB16: =SUM(Y16:AA16) -> 0 | AD16: =SUM(J16:K16)*2 -> 0 | AF16: -752926 | AG16: =(SUM(J16:K16)*2)-O16 -> 0
A17: -SIG SOFTWARE & CONSULTORIA EM TECNOLOGIA DA I (Serviço de apoio especializado nas atividades necessárias ao suporte negocial, customização e sustentação do Sistemas Institucionais Integrados de Gestão (SIG)) | B17: STI | C17: VGM01N01Q4N | D17: 13.406.686/0001-67 | E17: 23106.125254/2022-71 | F17: 46082 | G17: =IF((F17-TODAY())<0,"EXPIRADO", IF((F17-TODAY())<=60,"EM BREVE","NO PRAZO")) -> NO PRAZO | I17: 505/2024 | J17: =L17/12 -> 236095 | K17: ainda sem histórico de liquidação | L17: 2833140 | M17: 0 | N17: 0 | O17: =SUM(M17:N17) -> 0 | S17: =236037-202037 -> 34000 | Z17: =J17 -> 236095 | AA17: =J17 -> 236095 | AB17: =SUM(Y17:AA17) -> 472190 | AD17: =SUM(J17:K17)*2 -> 472190 | AF17: -99075 | AG17: =(SUM(J17:K17)*2)-O17 -> 472190
A18: Inframérica - Agenciamento de Carga Internacional (conforme demanda) | B18: Contratos DCO | C18: VGM01N01L3N | D18: 15559082000186 | E18: 23106.011.137/2014-11 23106.086385/2019-20 | F18: 45743 | G18: =IF((F18-TODAY())<0,"EXPIRADO", IF((F18-TODAY())<=60,"EM BREVE","NO PRAZO")) -> EXPIRADO | I18: 026/2020 | M18: 0 | N18: 0 | O18: =SUM(M18:N18) -> 0 | AB18: =SUM(Y18:AA18) -> 0 | AD18: =SUM(J18:K18)*2 -> 0 | AE18: =O18-AD18 -> 0
A19: Inframérica - prestação de serviços de armazenagem e capatazia de cargas importadas (conforme demanda) | B19: Contratos DCO | C19: VGM01N01L3N | D19: 15.559.082/0001-86 | E19: 23106.010064/2025-01 | F19: 47682 | G19: =IF((F19-TODAY())<0,"EXPIRADO", IF((F19-TODAY())<=60,"EM BREVE","NO PRAZO")) -> NO PRAZO | I19: 1203/2025 | J19: 4000 | L19: =J19*12 -> 48000 | M19: 42484.67 | O19: =SUM(M19:N19) -> 42484.67 | AB19: =SUM(Y19:AA19) -> 0
A20: Agenciamento de Transportes de Cargas Internacionais WeghLogística (Aéreos e Marítimos) (conforme demanda) não será prorrogado, licitação em andamento | B20: Contratos DCO/ DIMEX | C20: VGM01N01L3N | D20: 65494742000166 | E20: 23106.099324/2016-80 | F20: 45106 | G20: =IF((F20-TODAY())<0,"EXPIRADO", IF((F20-TODAY())<=60,"EM BREVE","NO PRAZO")) -> EXPIRADO | I20: 081/2017 | L20: 225342 | N20: =17567.67 -> 17567.67 | O20: =SUM(M20:N20) -> 17567.67 | AB20: =SUM(Y20:AA20) -> 0
A21: WEGH Assessoria e Logística Internacional Ltda, Agenciamento de Transportes de Cargas Internacionais WeghLogística | B21: Contratos DCO | C21: VGM01N01L3N | D21: 65494742000166 | E21: 23106.019323/2023-99 23106.087339/2024-13 (importação/ressarcimento) | F21: 46221 | G21: =IF((F21-TODAY())<0,"EXPIRADO", IF((F21-TODAY())<=60,"EM BREVE","NO PRAZO")) -> NO PRAZO | I21: 142/2023 | J21: 4000 | L21: =J21*12 -> 48000 | M21: 11897.6 | N21: 102.4 | O21: =SUM(M21:N21) -> 12000 | AB21: =SUM(Y21:AA21) -> 0 | AD21: =SUM(J21:K21)*2 -> 8000
A22: NK LOGISTICA E TRANSPORTES LTDA (serviços de transporte de cargas por via aérea) | B22: Contratos DCO | C22: VGM01N01P2N | D22: 32270711000172 | E22: 23106.068904/2022-73 | F22: 45989 | G22: =IF((F22-TODAY())<0,"EXPIRADO", IF((F22-TODAY())<=60,"EM BREVE","NO PRAZO")) -> EM BREVE | H22: em renovação | I22: 130/2022 | J22: 500 | L22: =J22*12 -> 6000 | N22: 57249.08 | O22: =SUM(M22:N22) -> 57249.08 | AB22: =SUM(Y22:AA22) -> 0
A23: - Seguro de aluno/ estagiário (MBM Seguradora S.A) | B23: Contratos DCO | C23: VGM01N01N7N | D23: 87883807000106 | E23: 23106.085902/2019-43 | F23: 46086 | G23: =IF((F23-TODAY())<0,"EXPIRADO", IF((F23-TODAY())<=60,"EM BREVE","NO PRAZO")) -> NO PRAZO | I23: 024/2020 | J23: 3870 | L23: 48000 | M23: 18060.8 | N23: 0 | O23: =SUM(M23:N23) -> 18060.8 | AB23: =SUM(Y23:AA23) -> 0 | AD23: =SUM(J23:K23)*2 -> 7740
A24: BELFORT GERENCIAMENTO DE RESIDUOS LTDA - empresa especializada nos serviços continuados de coleta, transporte, tratamento e disposição final de resíduos de serviços de saúde (RSS) | B24: Contratos DCA | C24: VGM01N01E4N | D24: 10865146000153 | E24: 23106.065223/2022-53 | F24: 46039 | G24: =IF((F24-TODAY())<0,"EXPIRADO", IF((F24-TODAY())<=60,"EM BREVE","NO PRAZO")) -> EM BREVE | I24: 1204/2023 | J24: 4000 | L24: =J24*12 -> 48000 | M24: 6981.19 | N24: 0 | O24: =SUM(M24:N24) -> 6981.19 | R24: =J24-O24 -> -2981.19 | S24: =J24-1948 -> 2052 | AA24: =J24*2-O24 -> 1018.81 | AB24: =SUM(Y24:AA24) -> 1018.81 | AD24: =SUM(J24:K24)*2 -> 8000 | AE24: =O24-AD24 -> -1018.81
A25: - NORESA NOVO RIO ENERGIA E SERVICOS AMBIENTAIS (empresa especializada na prestação de serviços de coleta, transporte, triagem e destinação final de resíduos sólidos orgânicos) | B25: PRC | C25: VGM01N01E4N | D25: 7044248000101 | E25: 23106.076421/2022-42 | F25: 45824 | G25: =IF((F25-TODAY())<0,"EXPIRADO", IF((F25-TODAY())<=60,"EM BREVE","NO PRAZO")) -> EXPIRADO | H25: DCA 12646146 Não será prorrogado, veirificar se há novo processo | I25: 1213/2023 | J25: 7000 | L25: =J25*12 -> 84000 | M25: 3179.7 | O25: =SUM(M25:N25) -> 3179.7 | R25: =J25 -> 7000 | AB25: =SUM(Y25:AA25) -> 0 | AD25: =SUM(J25:K25)*2 -> 14000 | AF25: =-Z25 -> 0 | AG25: =(SUM(J25:K25)*2)-O25 -> 10820.3
A26: PRIME EXTINTORES EIRELI – ME – recarga de extintores | B26: PRC | C26: VGM01N01I6N | D26: 09.098.197/0001-18 | E26: 23106.101317/2023-84 | F26: 46137 | G26: =IF((F26-TODAY())<0,"EXPIRADO", IF((F26-TODAY())<=60,"EM BREVE","NO PRAZO")) -> NO PRAZO | I26: 618/2024 | J26: 10000 | L26: 187401.54 | M26: 159010.09 | N26: 38595.64 | O26: =SUM(M26:N26) -> 197605.73 | AB26: =SUM(Y26:AA26) -> 0 | AD26: =SUM(J26:K26)*2 -> 20000 | AE26: =O26-AD26 -> 177605.73
A27: - Fornecimento de combustível (Novo fornecer para 2019 - Ticket soluções HDFGT S/A) (NÃO DEVE SER ANULADO) | B27: PRC | C27: VGM01N01I5N | D27: 3506307000157 | E27: 23106.116807/2021-13 | F27: 46270 | G27: =IF((F27-TODAY())<0,"EXPIRADO", IF((F27-TODAY())<=60,"EM BREVE","NO PRAZO")) -> NO PRAZO | I27: 1222/2022 | J27: 80000 | L27: =J27*12 -> 960000 | M27: 435769.35 | N27: 0 | O27: =SUM(M27:N27) -> 435769.35 | W27: =80000-12226 -> 67774 | AB27: =SUM(Y27:AA27) -> 0 | AD27: =SUM(J27:K27)*2 -> 160000 | AF27: =O27-AD27 -> 275769.35
A28: CRUZEIRO CONTROLE DE PRAGAS E DESENTUPIMENTO | B28: PRC | C28: VGM01N01D3N | D28: 22.575.793/0001-00 | E28: 23106.058637/2021-45 | F28: 45980 | G28: =IF((F28-TODAY())<0,"EXPIRADO", IF((F28-TODAY())<=60,"EM BREVE","NO PRAZO")) -> EM BREVE | H28: Em fase de prorrogação | I28: 1222/2024 | J28: =L28/12 -> 65625.02 | L28: 787500.24 | M28: 110567.4 | N28: 0 | O28: =SUM(M28:N28) -> 110567.4 | T28: =J28-O28 -> -44942.38 | U28: =J28-60820 -> 4805.02 | V28: =J28-60820 -> 4805.02 | AA28: =J28 -> 65625.02 | AB28: =SUM(Y28:AA28) -> 65625.02 | AG28: =(SUM(J28:K28)*2)-O28 -> 20682.64
A29: VILELA SERVIÇO DE PAISAGISMO, PARQUES E JARDINS LTDA (jardinagem) | B29: PRC | C29: VGM01N01A5N | D29: 32.751.565/0001-05 | E29: 23106.028705/2019-27 | F29: 46231 | G29: =IF((F29-TODAY())<0,"EXPIRADO", IF((F29-TODAY())<=60,"EM BREVE","NO PRAZO")) -> NO PRAZO | I29: 1217/2023 | J29: 298000 | L29: 3119907.7 | M29: 656695.86 | N29: 0 | O29: =SUM(M29:N29) -> 656695.86 | S29: =291576.42-21573 -> 270003.42 | T29: =J29-O29 -> -358695.86 | U29: =J29 -> 298000 | V29: =J29-271060 -> 26940 | AB29: =SUM(Y29:AA29) -> 0 | AD29: =SUM(J29:K29)*2 -> 596000 | AE29: =O29-AD29 -> 60695.86 | AG29: =(SUM(J29:K29)*2)-O29 -> -60695.86
A30: - TRANSMONICI TRANSPORTE E TURISMO (ônibus rodoviário executivo) | B30: PRC | C30: VGM01N01K1N | D30: 09169349000126 | E30: 23106.000890/2021-18 | F30: 46062 | G30: =IF((F30-TODAY())<0,"EXPIRADO", IF((F30-TODAY())<=60,"EM BREVE","NO PRAZO")) -> NO PRAZO | I30: 604/2022 | J30: 90000 | L30: =J30*12 -> 1080000 | M30: 286227.56 | N30: 0 | O30: =SUM(M30:N30) -> 286227.56 | AB30: =SUM(Y30:AA30) -> 0 | AD30: =SUM(J30:K30)*2 -> 180000 | AG30: =(SUM(J30:K30)*2)-O30 -> -106227.56
A31: Tafa Engenharia (serviços continuados de manutenção preventiva e corretiva de equipamentos e sistemas de ar condicionado, com fornecimento de peças e materiais) | B31: PRC | C31: VGM01N01F1N | D31: 12859652000165 | E31: 23106.056117/2023-60 | F31: 46123 | G31: =IF((F31-TODAY())<0,"EXPIRADO", IF((F31-TODAY())<=60,"EM BREVE","NO PRAZO")) -> NO PRAZO | I31: 616/2024 | K31: 95000 | L31: 1173817 | M31: 193101.91 | N31: 0 | O31: =SUM(M31:N31) -> 193101.91 | S31: =95000-46623 -> 48377 | AB31: =SUM(Y31:AA31) -> 0 | AD31: =SUM(J31:K31)*2 -> 190000 | AF31: -143541.49
A32: - Taxigov (demanda) - VIP service | B32: PRC | C32: VGM01N01A4N | D32: 02605452000122 | E32: 23106.010532/2020-24 | F32: 46094 | G32: =IF((F32-TODAY())<0,"EXPIRADO", IF((F32-TODAY())<=60,"EM BREVE","NO PRAZO")) -> NO PRAZO | I32: 036/2020 | J32: 6000 | L32: =J32*12 -> 72000 | M32: 47621.01 | N32: 0 | O32: =SUM(M32:N32) -> 47621.01 | AB32: =SUM(Y32:AA32) -> 0 | AD32: =SUM(J32:K32)*2 -> 12000 | AF32: -2000
A33: 3P HGM solução visual (serviços de comunicação visual) | B33: PRC | C33: VGM01N01O7N | D33: 34.998.513/0001-55 | E33: 23106.089249/2019-91 | F33: 46224 | G33: =IF((F33-TODAY())<0,"EXPIRADO", IF((F33-TODAY())<=60,"EM BREVE","NO PRAZO")) -> NO PRAZO | I33: 1217/2022 | J33: 500000 | L33: =J33*12 -> 6000000 | M33: 950140.51 | N33: 0 | O33: =SUM(M33:N33) -> 950140.51 | R33: =500000-83593 -> 416407 | S33: =500000-83593 -> 416407 | T33: 500000 | W33: =500000-208156 -> 291844 | AA33: =J33*2-O33 -> 49859.49 | AB33: =SUM(Y33:AA33) -> 49859.49 | AD33: =SUM(J33:K33)*2 -> 1000000 | AE33: =O33-AD33 -> -49859.49 | AG33: =(SUM(J33:K33)*2)-O33 -> 49859.49
A34: NP TECNOLOGIA E GESTAO DE DADOS LTDA - ferramenta de pesquisa e comparação de preços praticados pela Administração Pública | B34: PRC | C34: VGM01N01P6N | D34: 07.797.967/0001-95 | E34: 23106.108257/2021-69 | F34: 46098 | G34: =IF((F34-TODAY())<0,"EXPIRADO", IF((F34-TODAY())<=60,"EM BREVE","NO PRAZO")) -> NO PRAZO | H34: contrato anual | I34: 605/2022 | L34: 11456.99 | M34: 0 | O34: =SUM(M34:N34) -> 0 | AB34: =SUM(Y34:AA34) -> 0
A35: contratação de empresa especializada na prestação de serviços continuados, sem dedicação exclusiva de mão de obra, para realização de serviços de acondicionamento, coleta, transporte, tratamento e disposição final de resíduos químicos perigosos | C35: VGM01N01B8 | E35: 23106.043884/2024-90 | AB35: =SUM(Y35:AA35) -> 0
A36: ARTES GRÁFICA COMÉRCIO E REPRESENTAÇÕES EIRELI (serviços continuados de Designer Gráfico) - foi solicitada prorrogação por 20 meses | B36: Contratos DCA | C36: VGM01N01P4N | D36: 05606994000108 | E36: 23106.148085/2022-47 | F36: 46127 | G36: =IF((F36-TODAY())<0,"EXPIRADO", IF((F36-TODAY())<=60,"EM BREVE","NO PRAZO")) -> NO PRAZO | I36: 147/2022 | K36: =12640.77 -> 12640.77 | L36: =K36*12 -> 151689.24 | M36: 25281.54 | N36: 0 | O36: =SUM(M36:N36) -> 25281.54 | T36: =K36-536 -> 12104.77 | V36: =K36 -> 12640.77 | AB36: =SUM(Y36:AA36) -> 0 | AD36: =SUM(J36:K36)*2 -> 25281.54 | AE36: =O36-AD36 -> 0 | AG36: =(SUM(J36:K36)*2)-O36 -> 0
A37: ELYON BRASIL - ESPLANADA SERVICOS TERCEIRIZADOS EIRELI - serviços continuados de pessoal - coletores de resíduos de serviços de saúde | B37: Contratos DCA | C37: VGM01N01E4N | D37: 01099686000182 | E37: 23106.031888/2020-00 | F37: 46219 | G37: =IF((F37-TODAY())<0,"EXPIRADO", IF((F37-TODAY())<=60,"EM BREVE","NO PRAZO")) -> NO PRAZO | I37: 111/2020 | K37: =L37/12 -> 22669.34 | L37: 272032.08 | M37: 63344.59 | N37: 0 | O37: =SUM(M37:N37) -> 63344.59 | T37: =22669-1831.59 -> 20837.41 | W37: =K37-1000 -> 21669.34 | AB37: =SUM(Y37:AA37) -> 0 | AD37: =SUM(J37:K37)*2 -> 45338.68 | AE37: =O37-AD37 -> 18005.91 | AG37: =(SUM(J37:K37)*2)-O37 -> -18005.91
A38: - ALFA E OMEGA Apoio Técnico EDU | B38: Contratos DCA | C38: VGM01N01D5N | D38: 16650774000106 | E38: 23106.011967/2019-52 | F38: 46131 | G38: =IF((F38-TODAY())<0,"EXPIRADO", IF((F38-TODAY())<=60,"EM BREVE","NO PRAZO")) -> NO PRAZO | I38: 022/2021 | K38: =L38/12 -> 24316.78 | L38: 291801.36 | M38: 52521.99 | N38: 0 | O38: =SUM(M38:N38) -> 52521.99 | R38: 865.66 | S38: =K38-2497 -> 21819.78 | T38: =K38-22360 -> 1956.78 | U38: =K38 -> 24316.78 | AB38: =SUM(Y38:AA38) -> 0 | AD38: =SUM(J38:K38)*2 -> 48633.56 | AE38: =O38-AD38 -> 3888.43 | AG38: =(SUM(J38:K38)*2)-O38 -> -3888.43
A39: RCS Tecnologia LTDA - copeiragem | B39: Contratos DCA | C39: VGM01N01O2N | D39: 8220952000122 | E39: 23106.125355/2019-46 23106.035022/2021-41 | F39: 45929 | G39: =IF((F39-TODAY())<0,"EXPIRADO", IF((F39-TODAY())<=60,"EM BREVE","NO PRAZO")) -> EXPIRADO | H39: Não será renovado | I39: 07/2021 | K39: 131667.49 | L39: =K39*12 -> 1580009.9 | M39: 61444.83 | N39: 0 | O39: =SUM(M39:N39) -> 61444.83 | S39: 131667 | U39: =K39 -> 131667.49 | Z39: =K39-O39 -> 70222.66 | AA39: =K39 -> 131667.49 | AB39: =SUM(Y39:AA39) -> 201890.15 | AD39: =SUM(J39:K39)*2 -> 263334.98 | AE39: =O39-AD39 -> -201890.15 | AG39: =(SUM(J39:K39)*2)-O39 -> 201890.15
A40: OBJETIVA SERVIÇOS TERCEIRIZADOS LTDA - copeiragem | B40: Contratos DCA | C40: VGM01N01O2N | D40: 10.874.523/0001-10 | E40: 23106.030343/2024-00 23106.093628/2025-24 | F40: 46660 | G40: =IF((F40-TODAY())<0,"EXPIRADO", IF((F40-TODAY())<=60,"EM BREVE","NO PRAZO")) -> NO PRAZO | I40: 24/2025 | K40: 155277.21 | L40: =K40*12 -> 1863326.5 | M40: 465831.63 | O40: =SUM(M40:N40) -> 465831.63 | AB40: =SUM(Y40:AA40) -> 0
...

Sheet Programação 17.11
A1: Acompanhamento de Contratos* | AA1: continuados | AB1: =#REF!+#REF!+AB4+AB5+#REF!+AB6+#REF!+AB9+SUM(AB14:AB18)+AB21+#REF!+AB22+#REF!+#REF!+#REF! -> #REF! | AC1: spi | AE1: ver observação | AH1: =SUM(AB24:AB29) -> 350001.99
A2: Data de Atualização: 10/11/2025 | AB2: =AB5+#REF!+AB9+#REF!+#REF!+AB14+#REF!+#REF!+AB15+AB16+AB17+#REF!+AB18+AB21+#REF!+AB22+#REF!+#REF!+#REF! -> #REF! | AC2: por demanda | AE2: NÃO ANULAR | AH2: =#REF!+AB6+AB7+AB10+#REF!+AB11+#REF!+#REF!+#REF!+#REF!+AB12+#REF!+#REF!+#REF!+#REF!+#REF!+AB13+#REF!+#REF!+AB23+AB32+AB33+AB34+#REF!+#REF!+#REF!+#REF!+#REF!+AB35 -> #REF!
A3: Descrição das despesas | B3: UGR | C3: PI 2025 | D3: CNPJ | E3: Processo | F3: Vigência | G3: Status do Contrato | H3: Situação da prorrogação | I3: nº Contrato | J3: Valor Contrato Média mensal | K3: Valor Cont Continuado Mensal | L3: Total estimado Anual | M3: Saldo Empenhos 2025 | N3: Saldo de Empenhos RAP | O3: Total RAP + Empenho | P3: 45658 | Q3: 45689 | R3: 45717 | S3: 45748 | T3: 45778 | U3: 45809 | V3: 45839 | W3: 45870 | X3: 45901 | Y3: 45931 | Z3: 45962 | AA3: 45992 | AB3: Total necessário | AC3: Causas Judiciais | AD3: OUT-NOV (2024) | AE3: Saldo passivel de Anulação | AF3: Necessidade de Empenho até Novembro | AG3: Necessidade Janeiro | AH3: =#REF!+#REF!+#REF! -> #REF!
A4: Pasep - HUB | B4: HUB | C4: VGM01N01N1N | J4: 49000 | L4: =48891*13.33 -> 651717.03 | M4: 90145.45 | O4: =SUM(M4:N4) -> 90145.45 | AA4: =J4*2-O4 -> 7854.55 | AB4: =SUM(Y4:AA4) -> 7854.55 | AC4: RU | AH4: =AB30 -> 1571668.7
A5: Pasep - UnB | B5: DGP/ folha | C5: VGM01N01N1N | J5: 810000 | L5: =J5*12 -> 9720000 | M5: 1492474.5 | N5: 0 | O5: =SUM(M5:N5) -> 1492474.5 | T5: =810000-556810 -> 253190 | U5: =J5 -> 810000 | V5: =J5 -> 810000 | AA5: =J5*2-O5 -> 127525.53 | AB5: =SUM(Y5:AA5) -> 127525.53 | AD5: =SUM(J5:K5)*2 -> 1620000 | AE5: =O5-AD5 -> -127525.53 | AG5: =(SUM(J5:K5)*2)-O5 -> 127525.53 | AH5: =AB2+AH1+AH2+AH3+#REF!+#REF!+AH4 -> #REF!
A6: Energia Elétrica UnB Cerrado - CONTRATO CCER - ENEL N. 36/2020 e CELG DISTRIBUIÇÃO S.A - CELG D, Equatorial Goiás Distribuidora de Energia S/A | B6: UnB Cerrado | C6: VGM01N01I2N | D6: 1543032000104 | E6: 23106.044802/2020-09 23106.083937/2023-24 | I6: 36/2020 | J6: 1585.03 | L6: =J6*12 -> 19020.36 | M6: =570.63+124.47 -> 695.1 | N6: 41.48 | O6: =SUM(M6:N6) -> 736.58 | U6: =J6-324 -> 1261.03 | W6: =1585-1230 -> 355 | Z6: =J6-O6 -> 848.45 | AA6: =J6 -> 1585.03 | AB6: =SUM(Y6:AA6) -> 2433.48 | AD6: =SUM(J6:K6)*2 -> 3170.06 | AE6: =O6-AD6 -> -2433.48 | AG6: =(SUM(J6:K6)*2)-O6 -> 2433.48
A7: OI SA recuperação judicial | B7: STI | C7: VGM01N01I4N | D7: 76535764000143 | E7: 23106.012727/2018-94 | F7: 46247 | G7: =IF((F7-TODAY())<0,"EXPIRADO", IF((F7-TODAY())<=60,"EM BREVE","NO PRAZO")) -> NO PRAZO | I7: 515/2021 | J7: 60000 | L7: =J7*12 -> 720000 | M7: 105024.66 | N7: 0 | O7: =SUM(M7:N7) -> 105024.66 | R7: =J7 -> 60000 | S7: =J7 -> 60000 | T7: =J7 -> 60000 | AA7: =J7*2-O7 -> 14975.34 | AB7: =SUM(Y7:AA7) -> 14975.34 | AD7: =SUM(J7:K7)*2 -> 120000 | AE7: =O7-AD7 -> -14975.34 | AF7: =-Y7-Z7 -> 0 | AG7: =(SUM(J7:K7)*2)-O7 -> 14975.34
A8: QUALIFICAR - Suporte TI (Serviços de Manutenção dos Computadores da UnB) | B8: STI | C8: VGM01N01A3N | D8: 04.752.792/0001-01 | E8: 23106.016945/2023-65 | F8: 46147 | G8: =IF((F8-TODAY())<0,"EXPIRADO", IF((F8-TODAY())<=60,"EM BREVE","NO PRAZO")) -> NO PRAZO | I8: 512/2025 | K8: =L8/12 -> 182288 | L8: 2187456 | M8: 323045.17 | N8: 0 | O8: =SUM(M8:N8) -> 323045.17 | U8: 182288 | AA8: =K8*2-O8 -> 41530.83 | AB8: =SUM(Y8:AA8) -> 41530.83 | AG8: =(SUM(J8:K8)*2)-O8 -> 41530.83
A9: -SIG SOFTWARE & CONSULTORIA EM TECNOLOGIA DA I (Serviço de apoio especializado nas atividades necessárias ao suporte negocial, customização e sustentação do Sistemas Institucionais Integrados de Gestão (SIG)) | B9: STI | C9: VGM01N01Q4N | D9: 13.406.686/0001-67 | E9: 23106.125254/2022-71 | F9: 46082 | G9: =IF((F9-TODAY())<0,"EXPIRADO", IF((F9-TODAY())<=60,"EM BREVE","NO PRAZO")) -> NO PRAZO | I9: 505/2024 | J9: =L9/12 -> 236095 | K9: ainda sem histórico de liquidação | L9: 2833140 | M9: 0 | N9: 0 | O9: =SUM(M9:N9) -> 0 | S9: =236037-202037 -> 34000 | Z9: =J9 -> 236095 | AA9: =J9 -> 236095 | AB9: =SUM(Y9:AA9) -> 472190 | AD9: =SUM(J9:K9)*2 -> 472190 | AF9: -99075 | AG9: =(SUM(J9:K9)*2)-O9 -> 472190
A10: Inframérica - Agenciamento de Carga Internacional (conforme demanda) | B10: Contratos DCO | C10: VGM01N01L3N | D10: 15559082000186 | E10: 23106.011.137/2014-11 23106.086385/2019-20 | F10: 45743 | G10: =IF((F10-TODAY())<0,"EXPIRADO", IF((F10-TODAY())<=60,"EM BREVE","NO PRAZO")) -> EXPIRADO | I10: 026/2020 | M10: 0 | N10: 0 | O10: =SUM(M10:N10) -> 0 | AB10: =SUM(Y10:AA10) -> 0 | AD10: =SUM(J10:K10)*2 -> 0 | AE10: =O10-AD10 -> 0
A11: BELFORT GERENCIAMENTO DE RESIDUOS LTDA - empresa especializada nos serviços continuados de coleta, transporte, tratamento e disposição final de resíduos de serviços de saúde (RSS) | B11: Contratos DCA | C11: VGM01N01E4N | D11: 10865146000153 | E11: 23106.065223/2022-53 | F11: 46039 | G11: =IF((F11-TODAY())<0,"EXPIRADO", IF((F11-TODAY())<=60,"EM BREVE","NO PRAZO")) -> EM BREVE | I11: 1204/2023 | J11: 4000 | L11: =J11*12 -> 48000 | M11: 6981.19 | N11: 0 | O11: =SUM(M11:N11) -> 6981.19 | R11: =J11-O11 -> -2981.19 | S11: =J11-1948 -> 2052 | AA11: =J11*2-O11 -> 1018.81 | AB11: =SUM(Y11:AA11) -> 1018.81 | AD11: =SUM(J11:K11)*2 -> 8000 | AE11: =O11-AD11 -> -1018.81
A12: CRUZEIRO CONTROLE DE PRAGAS E DESENTUPIMENTO | B12: PRC | C12: VGM01N01D3N | D12: 22.575.793/0001-00 | E12: 23106.058637/2021-45 | F12: 45980 | G12: =IF((F12-TODAY())<0,"EXPIRADO", IF((F12-TODAY())<=60,"EM BREVE","NO PRAZO")) -> EM BREVE | H12: Em fase de prorrogação | I12: 1222/2024 | J12: =L12/12 -> 65625.02 | L12: 787500.24 | M12: 110567.4 | N12: 0 | O12: =SUM(M12:N12) -> 110567.4 | T12: =J12-O12 -> -44942.38 | U12: =J12-60820 -> 4805.02 | V12: =J12-60820 -> 4805.02 | AA12: =J12 -> 65625.02 | AB12: =SUM(Y12:AA12) -> 65625.02 | AG12: =(SUM(J12:K12)*2)-O12 -> 20682.64
A13: 3P HGM solução visual (serviços de comunicação visual) | B13: PRC | C13: VGM01N01O7N | D13: 34.998.513/0001-55 | E13: 23106.089249/2019-91 | F13: 46224 | G13: =IF((F13-TODAY())<0,"EXPIRADO", IF((F13-TODAY())<=60,"EM BREVE","NO PRAZO")) -> NO PRAZO | I13: 1217/2022 | J13: 500000 | L13: =J13*12 -> 6000000 | M13: 950140.51 | N13: 0 | O13: =SUM(M13:N13) -> 950140.51 | R13: =500000-83593 -> 416407 | S13: =500000-83593 -> 416407 | T13: 500000 | W13: =500000-208156 -> 291844 | AA13: =J13*2-O13 -> 49859.49 | AB13: =SUM(Y13:AA13) -> 49859.49 | AD13: =SUM(J13:K13)*2 -> 1000000 | AE13: =O13-AD13 -> -49859.49 | AG13: =(SUM(J13:K13)*2)-O13 -> 49859.49
A14: RCS Tecnologia LTDA - copeiragem | B14: Contratos DCA | C14: VGM01N01O2N | D14: 8220952000122 | E14: 23106.125355/2019-46 23106.035022/2021-41 | F14: 45929 | G14: =IF((F14-TODAY())<0,"EXPIRADO", IF((F14-TODAY())<=60,"EM BREVE","NO PRAZO")) -> EXPIRADO | H14: Não será renovado | I14: 07/2021 | K14: 131667.49 | L14: =K14*12 -> 1580009.9 | M14: 61444.83 | N14: 0 | O14: =SUM(M14:N14) -> 61444.83 | S14: 131667 | U14: =K14 -> 131667.49 | Z14: =K14-O14 -> 70222.66 | AA14: =K14 -> 131667.49 | AB14: =SUM(Y14:AA14) -> 201890.15 | AD14: =SUM(J14:K14)*2 -> 263334.98 | AE14: =O14-AD14 -> -201890.15 | AG14: =(SUM(J14:K14)*2)-O14 -> 201890.15
A15: - RCA (Limpeza e Conservação) | B15: Contratos DCA | C15: VGM01N01A7N | D15: 69.207.850/0001-61 | E15: 23106.057738/2021-07 | F15: 46402 | G15: =IF((F15-TODAY())<0,"EXPIRADO", IF((F15-TODAY())<=60,"EM BREVE","NO PRAZO")) -> NO PRAZO | I15: 02/2022 | K15: 1918496.1 | L15: =K15*12 -> 23021953 | M15: 213422.1 | N15: 0 | O15: =SUM(M15:N15) -> 213422.1 | S15: =1882331-116567 -> 1765764 | T15: =1882331-116567 -> 1765764 | U15: =1882331-116567 -> 1765764 | V15: =1882331-116567 -> 1765764 | W15: =1882331-116567 -> 1765764 | X15: =1882331-116567 -> 1765764 | Z15: =K15-O15 -> 1705074 | AA15: =K15 -> 1918496.1 | AB15: =SUM(Y15:AA15) -> 3623570.1 | AD15: =SUM(J15:K15)*2 -> 3836992.2 | AF15: =O15-AD15 -> -3623570.1
A16: Life Defense (Segurança) | B16: Contratos DCA | C16: VGM01N01A8N | D16: 02674687000176 | E16: 23106.016977/2013-99 23106.083943/2018-14 23106.047642/2024-75 | F16: 46097 | G16: =IF((F16-TODAY())<0,"EXPIRADO", IF((F16-TODAY())<=60,"EM BREVE","NO PRAZO")) -> NO PRAZO | I16: 011/2020 | K16: 1617878.6 | L16: =K16*12 -> 19414543 | M16: 3235757.2 | N16: 0 | O16: =SUM(M16:N16) -> 3235757.2 | S16: =K16 -> 1617878.6 | U16: =K16 -> 1617878.6 | AB16: =SUM(Y16:AA16) -> 0 | AD16: =SUM(J16:K16)*2 -> 3235757.2 | AF16: =O16-AD16 -> 0 | AG16: =(SUM(J16:K16)*2)-O16 -> 0
A17: G&E SERVICOS TERCEIRIZADOS LTDA (PORTARIA) | B17: Contratos DCA | C17: VGM01N01A9N | D17: 08744139000151 | E17: 23106.085840/2022-75 23106.005560/2022-91 23106.046596/2024-97 | F17: 46020 | G17: =IF((F17-TODAY())<0,"EXPIRADO", IF((F17-TODAY())<=60,"EM BREVE","NO PRAZO")) -> EM BREVE | I17: 081/2022 | K17: =1412211.24 -> 1412211.2 | L17: =K17*12 -> 16946535 | M17: 1022222.7 | N17: 0 | O17: =SUM(M17:N17) -> 1022222.7 | R17: =K17-N17 -> 1412211.2 | S17: =1238299-555 -> 1237744 | U17: =K17 -> 1412211.2 | Z17: =K17-O17 -> 389988.51 | AA17: =K17 -> 1412211.2 | AB17: =SUM(Y17:AA17) -> 1802199.8 | AD17: =SUM(J17:K17)*2 -> 2824422.5 | AF17: =O17-AD17 -> -1802199.8 | AG17: =(SUM(J17:K17)*2)-O17 -> 1802199.8
A18: GRIFFO (recepcionista) | B18: Contratos DCA | C18: VGM01N01B3N | D18: 26426650000197 | E18: 23106.127519/2018-99; 23106.069857/2019-80 23106.070409/2023-13 | F18: 46221 | G18: =IF((F18-TODAY())<0,"EXPIRADO", IF((F18-TODAY())<=60,"EM BREVE","NO PRAZO")) -> NO PRAZO | I18: 071/2024 | K18: 163496.8 | L18: =K18*12 -> 1961961.6 | M18: 163496.8 | N18: 0 | O18: =SUM(M18:N18) -> 163496.8 | V18: =K18 -> 163496.8 | W18: =K18 -> 163496.8 | AA18: =K18 -> 163496.8 | AB18: =SUM(Y18:AA18) -> 163496.8 | AD18: =SUM(J18:K18)*2 -> 326993.6 | AE18: =O18-AD18 -> -163496.8 | AG18: =(SUM(J18:K18)*2)-O18 -> 163496.8
A19: MPE ENGENHARIA E SERVICOS S/A (serviços comuns de engenharia, incluindo manutenção, conservação, adaptação, reparação e instalação de infraestruturas prediais e imobiliárias) - (exceto DAC) | B19: Contratos DCA | C19: VGM01N01H3N | D19: 04743858000105 | E19: 23106.149436/2022-37 | F19: 46114 | G19: =IF((F19-TODAY())<0,"EXPIRADO", IF((F19-TODAY())<=60,"EM BREVE","NO PRAZO")) -> NO PRAZO | I19: 1201/2023 | J19: 1600000 | L19: =J19*12 -> 19200000 | M19: 435887.47 | N19: 0 | O19: =SUM(M19:N19) -> 435887.47 | U19: =J19-836351 -> 763649 | V19: =J19-1393762 -> 206238 | W19: =J19-460192 -> 1139808 | Z19: =J19-O19 -> 1164112.5 | AA19: 1998000 | AB19: =SUM(Y19:AA19) -> 3162112.5 | AD19: =SUM(J19:K19)*2 -> 3200000 | AF19: -419070 | AG19: =(SUM(J19:K19)*2)-O19 -> 2764112.5
A20: MPE - Adequação e impermeabilização | B20: Contratos DCA | C20: VGA02N43E3N | D20: 04743858000105 | E20: 23106.149228/2022-38 | F20: 46022 | G20: =IF((F20-TODAY())<0,"EXPIRADO", IF((F20-TODAY())<=60,"EM BREVE","NO PRAZO")) -> EM BREVE | H20: em fase de renovação | I20: 1110/2024 | J20: =L20/12 -> 1924342.1 | L20: =8383552.34+14708553.16 -> 23092106 | M20: 33.64 | O20: =SUM(M20:N20) -> 33.64 | U20: =J20-O20 -> 1924308.5 | W20: =1924342-1832108 -> 92234 | Z20: =J20 -> 1924342.1 | AB20: =SUM(Y20:AA20) -> 1924342.1 | AD20: =SUM(J20:K20)*2 -> 3848684.2 | AF20: =-AB20 -> -1924342.1 | AG20: =(SUM(J20:K20)*2)-O20 -> 3848650.6
A21: Ágil (Serviços Agropecuários) | B21: Contratos DCA | C21: VGM01N01C5N | D21: 72620735000129 | E21: 23106.076196/2018-68 23106.030688/2022-93 | F21: 46097 | G21: =IF((F21-TODAY())<0,"EXPIRADO", IF((F21-TODAY())<=60,"EM BREVE","NO PRAZO")) -> NO PRAZO | I21: 25/2020 | K21: 484202.15 | L21: =K21*12 -> 5810425.8 | M21: 917231.82 | O21: =SUM(M21:N21) -> 917231.82 | R21: =K21-N21 -> 484202.15 | U21: =K21 -> 484202.15 | AA21: =K21*2-O21 -> 51172.48 | AB21: =SUM(Y21:AA21) -> 51172.48 | AD21: =SUM(J21:K21)*2 -> 968404.3 | AE21: =O21-AD21 -> -51172.48 | AG21: =(SUM(J21:K21)*2)-O21 -> 51172.48
A22: - Segurança - ULTRASEG Segurança Patrimonial Ltda | B22: UnB Cerrado | C22: VGM01N01A8N | D22: 09151154000159 | E22: 23106.020717/2022-17 | F22: 46303 | G22: =IF((F22-TODAY())<0,"EXPIRADO", IF((F22-TODAY())<=60,"EM BREVE","NO PRAZO")) -> NO PRAZO | I22: 1207/2022 | K22: 23452.22 | L22: =K22*12 -> 281426.64 | M22: 1000 | N22: 0 | O22: =SUM(M22:N22) -> 1000 | U22: =K22 -> 23452.22 | Z22: =K22-O22 -> 22452.22 | AA22: =K22 -> 23452.22 | AB22: =SUM(Y22:AA22) -> 45904.44 | AD22: =SUM(J22:K22)*2 -> 46904.44 | AF22: -46904.36 | AG22: =(SUM(J22:K22)*2)-O22 -> 45904.44
A23: Jardinagem - UnB Cerrado - AMBIENTAL DO BRASIL ESTUDOS E PROJETOS AMBIENTAIS LTDA | B23: UnB Cerrado | C23: VGM01N01A5N | D23: 09150575000165 | E23: 23106.092536/2018-06 | F23: 46309 | G23: =IF((F23-TODAY())<0,"EXPIRADO", IF((F23-TODAY())<=60,"EM BREVE","NO PRAZO")) -> NO PRAZO | I23: 659/2020 | J23: =L23/12 -> 4106.25 | L23: 49275 | M23: 7891.86 | N23: 0 | O23: =SUM(M23:N23) -> 7891.86 | AA23: =J23*2-O23 -> 320.64 | AB23: =SUM(Y23:AA23) -> 320.64 | AD23: =SUM(J23:K23)*2 -> 8212.5 | AF23: =-Y23*2 -> 0
A24: Engemega - (Manutenção de Imóveis gerenciados pela Secretaria de Patrimônio Imobiliário (SPI)) – contrato 1 (contrato antigo) | B24: Contratos SPI | C24: VGM01N01D4N | D24: 33480104/0001-08 | E24: 23106.059077/2021-46 | F24: 46035 | G24: =IF((F24-TODAY())<0,"EXPIRADO", IF((F24-TODAY())<=60,"EM BREVE","NO PRAZO")) -> EM BREVE | I24: 1223/2022 | J24: 309551 | L24: 6773742 | M24: 590994.48 | O24: =SUM(M24:N24) -> 590994.48 | R24: =J24-M24 -> -281443.48 | AA24: =J24*2-O24 -> 28107.52 | AB24: =SUM(Y24:AA24) -> 28107.52 | AD24: =J24*2 -> 619102 | AE24: =O24-AD24 -> -28107.52 | AG24: =(SUM(J24:K24)*2)-O24 -> 28107.52
A25: FORMIGA ENGENHARIA E ARQUITETURA LTDA, especializada na prestação de serviços continuados, sem dedicação exclusiva de mão de obra, para realização de vistorias de entrada e saída nos imóveis de propriedade da Universidade de Brasília | B25: Contratos SPI | C25: VGM01N01D2N | D25: 22.352.353/0001-93 | E25: 23106.013588/2024-64 | F25: 46340 | G25: =IF((F25-TODAY())<0,"EXPIRADO", IF((F25-TODAY())<=60,"EM BREVE","NO PRAZO")) -> NO PRAZO | I25: 93/2024 | J25: =L25/12 -> 7018 | L25: 84216 | M25: 4754 | N25: 726 | O25: =SUM(M25:N25) -> 5480 | Z25: =J25-O25 -> 1538 | AA25: =J25 -> 7018 | AB25: =SUM(Y25:AA25) -> 8556 | AG25: =(SUM(J25:K25)*2)-O25 -> 8556
A26: SILVA EDIFICAÇÕES LTDA - emissão de laudos técnicos de avaliação de valores imobiliários | B26: Contratos SPI | C26: VGM01N01Q7N | D26: 44.532.592/0001-68 | E26: 23106.103034/2024-58 | F26: 46327 | G26: =IF((F26-TODAY())<0,"EXPIRADO", IF((F26-TODAY())<=60,"EM BREVE","NO PRAZO")) -> NO PRAZO | I26: 1220/2024 | J26: =L26/12 -> 832.5 | L26: 9990 | M26: 1638 | N26: 0 | O26: =SUM(M26:N26) -> 1638 | R26: =J26-O26 -> -805.5 | S26: =J26-27 -> 805.5 | T26: =J26 -> 832.5 | AA26: =J26*2-O26 -> 27 | AB26: =SUM(Y26:AA26) -> 27
A27: HONIX (elevadores) (01 de um mês a 30 do mesmo mês) | B27: Contratos SPI | C27: VGM01N01I7N | D27: 21051130000123 | E27: 23106.053280/2018-11 | F27: 45920 | G27: =IF((F27-TODAY())<0,"EXPIRADO", IF((F27-TODAY())<=60,"EM BREVE","NO PRAZO")) -> EXPIRADO | H27: Não será renovado | I27: 090/2019 | K27: =L27/12 -> 39124.22 | L27: 469490.64 | M27: 34750.02 | O27: =SUM(M27:N27) -> 34750.02 | Z27: =K27-O27 -> 4374.2 | AA27: =K27 -> 39124.22 | AB27: =SUM(Y27:AA27) -> 43498.42 | AD27: =SUM(J27:K27)*2 -> 78248.44 | AE27: =O27-AD27 -> -43498.42 | AG27: =(SUM(J27:K27)*2)-O27 -> 43498.42
A28: - CAESB - SPI | B28: Contratos SPI | C28: VGM01N01I3N | D28: 00082024000137 | J28: 136350 | L28: =J28*12 -> 1636200 | M28: 251998.44 | N28: 0 | O28: =SUM(M28:N28) -> 251998.44 | R28: =J28-O28 -> -115648.44 | S28: =J28 -> 136350 | V28: =J28-1163 -> 135187 | AA28: =J28*2-O28 -> 20701.56 | AB28: =SUM(Y28:AA28) -> 20701.56 | AD28: =J28*2 -> 272700 | AE28: =O28-AD28 -> -20701.56
A29: - Despesas de Condomínio | B29: Contratos SPI | C29: VGM01N01K6N | E29: 23106.134844/2020-22 | J29: 245000 | L29: =J29*12 -> 2940000 | M29: 240888.51 | N29: 0 | O29: =SUM(M29:N29) -> 240888.51 | R29: =J29-O29 -> 4111.49 | T29: =J29-8976 -> 236024 | U29: =J29-49349 -> 195651 | Z29: =J29-O29 -> 4111.49 | AA29: =J29 -> 245000 | AB29: =SUM(Y29:AA29) -> 249111.49 | AD29: =J29*2 -> 490000 | AE29: =O29-AD29 -> -249111.49 | AG29: =(SUM(J29:K29)*2)-O29 -> 249111.49
A30: Restaurante ISM EIRELI (diretoria RU) - Ação 20RK planilha DRU | B30: Contrato DAC/RU | C30: VGM01N01B5N | D30: 04228626001263 | E30: 23106.013653/2020-28 | F30: 46274 | G30: =IF((F30-TODAY())<0,"EXPIRADO", IF((F30-TODAY())<=60,"EM BREVE","NO PRAZO")) -> NO PRAZO | I30: 31/2021 | J30: =L30/12 -> 1500933.6 | L30: 18011203 | M30: 1726196.1 | N30: 0 | O30: =SUM(M30:N30) -> 1726196.1 | U30: ='DRU 25'!J10 -> 1791326.9 | Z30: =1791326.86-O30 -> 65130.77 | AA30: 1506537.9 | AB30: =SUM(Y30:AA30) -> 1571668.7 | AD30: =Y30+Z30 -> 65130.77 | AG30: =(SUM(J30:K30)*2)-O30 -> 1275671
A31: - Serviço manutenção piscinas Casa Niemeyer | B31: Contratos Diversos | C31: VGM01N01N5N | O31: =SUM(M31:N31) -> 0 | AB31: =SUM(Y31:AA31) -> 0 | AG31: =(SUM(J31:K31)*2)-O31 -> 0
A32: - Ajuda de custo (Redistribuição de servidores) | B32: Contratos Diversos | C32: VGH01N0111N | J32: 20000 | L32: =J32*12 -> 240000 | M32: 0 | N32: 0 | O32: =SUM(M32:N32) -> 0 | R32: =J32 -> 20000 | S32: =J32 -> 20000 | T32: =J32 -> 20000 | U32: =J32 -> 20000 | V32: =J32 -> 20000 | W32: =J32 -> 20000 | Z32: =J32 -> 20000 | AA32: =J32 -> 20000 | AB32: =SUM(Y32:AA32) -> 40000 | AG32: =(SUM(J32:K32)*2)-O32 -> 40000
A33: Cespe (despesas diversas) | B33: CESPE | C33: VGR02N01A1N | E33: 23106.019902/2017-93 | J33: 70000 | L33: =J33*12 -> 840000 | M33: 101505.99 | N33: 25585.25 | O33: =SUM(M33:N33) -> 127091.24 | T33: =J33-7000 -> 63000 | U33: =J33 -> 70000 | AA33: =J33*2-N33 -> 114414.75 | AB33: =SUM(Y33:AA33) -> 114414.75 | AD33: =J33*2 -> 140000 | AE33: =O33-AD33-N33 -> -38494.01
A34: CEBRASPE (Processos seletivos UnB) | B34: DEG | C34: VGM01N01J5N | D34: 18284407000153 | E34: 23106.098851/2020-53 23106.018871/2022-11 23106.093468/2021-90 23106.065413/2023-51 23106.065557/2023-16 23106.035963/2024-27 | F34: 46734 | G34: =IF((F34-TODAY())<0,"EXPIRADO", IF((F34-TODAY())<=60,"EM BREVE","NO PRAZO")) -> NO PRAZO | I34: diversos | J34: 280000 | L34: =J34*12 -> 3360000 | M34: 42971.08 | N34: 320755.17 | O34: =SUM(M34:N34) -> 363726.25 | AA34: =J34*2-O34 -> 196273.75 | AB34: =SUM(Y34:AA34) -> 196273.75 | AD34: =J34*2 -> 560000
A35: - SIMPRESS - Outsourcing de serviços de impressão | B35: Contratos custeados pelas Unidades (STI) | C35: VGM01N01M8N | D35: 07432517000107 | E35: 23106.000978/2016-64 23106.010988/2019-51 | F35: 46022 | G35: =IF((F35-TODAY())<0,"EXPIRADO", IF((F35-TODAY())<=60,"EM BREVE","NO PRAZO")) -> EM BREVE | I35: 512/2021 | J35: =62000*104.4% -> 64728 | L35: =J35*12 -> 776736 | M35: 33015.44 | N35: 0 | O35: =SUM(M35:N35) -> 33015.44 | Z35: =J35-O35 -> 31712.56 | AA35: =J35 -> 64728 | AB35: =SUM(Y35:AA35) -> 96440.56 | AD35: =J35*2 -> 129456 | AF35: -60500.4 | AG35: =(SUM(J35:K35)*2)-O35 -> 96440.56
AG36: =(SUM(J36:K36)*3)-O36 -> 0
A37: Total da despesa | J37: =SUM(J4:J35) -> 7889166.5 | K37: =SUM(K4:K35) -> 5972816.8 | L37: =SUM(L4:L35) -> 1.6946665e+08 | M37: =SUM(M4:M35) -> 12166174 | N37: =SUM(N4:N35) -> 347107.9 | O37: =SUM(O4:O35) -> 12513282 | P37: =SUM(P4:P35) -> 0 | Q37: =SUM(Q4:Q35) -> 0 | ... AB37: =SUM(AB4:AB35) -> 14126822 | AD37: =SUM(AD4:AD35) -> 24137703 | AE37: =SUM(AE4:AE35) -> -992285.08 | AF37: =SUM(AF4:AF35) -> -7975661.7 | AG37: =SUM(AG4:AG35) -> 11348009
AF39: =AF20 -> -1924342.1
AF40: -6000000
AF41: -1280820.9
...

Sheet Bolsas
A2: Descrição das despesas | B2: Prioridade | C2: PI 2024 | D2: Saldo Empenhos 2024 | E2: Saldo de Empenhos RAP
A3: Auxílio financeiro a estudantes - DEX | C3: VXX01N21C3N | D3: 282726.47 | E3: 59839
A4: Auxílio financeiro a estudantes - DEX | C4: VGY01N0106N | D4: 316300
A5: Auxílio financeiro a estudantes - DEG | C5: MEG01G55B8N | D5: 58250 | E5: 0
A6: Auxílio financeiro a estudantes - DEG | C6: VGY01N0106N | D6: 168955.15 | E6: 48690.66
A7: Auxílio financeiro a estudantes - DPI | C7: MEG01G55B9N | E7: 61000
A8: Auxílio financeiro a estudantes - DPI | C8: VGY01N0106N
A9: Auxílio financeiro a estudantes - DPG | C9: OEP01O55A4N | E9: 392100
A10: Auxílio financeiro a estudantes - DPG | C10: VGY01N0106N | D10: 2100 | E10: 794.54
A11: AUXILIO SOCIOECONOMICO - DAC | C11: MGU01N23A1N
A12: BOLSA INCLUSAO DIGITAL - DAC | C12: MGU01N23B4N | E12: 102850
A13: - Bolsas PIBIC (DPG) - faz parte do PROIC | C13: NEG01G19A5N NEG03G19A5N
A14: - Bolsas PROIC (DPG) | C14: NQQ01G20A1N | D14: 252700
A15: - Bolsa estudante de graduação CEAD | C15: MEG01G19B5N | E15: 122246.09
A16: - Bolsa estudante de pós-graduação CEAD | C16: MEG01G19B5N
A17: - Auxílio financeiro a professor CEAD | C17: MEG01G19B5N
A18: Bolsas de Extensão (DEX) | C18: VGM01N01M3N
A19: - Bolsas concedidas pela CAPES | C19: OGP01O19A1N
A20: - Auxílio Financeiro a Pesquisador (DPI) | C20: NQQ01N55C5N | D20: 1018895.1 | E20: 973046.26
A21: Auxílio Financeiro a Pesquisador (DEG) | C21: NQQ01N55C5N VGY01N0106N
A22: - Auxílio Financeiro a Pesquisador (DEX) | C22: VXX01N21C2N VGY01N0106N
A23: - Auxílio Financeiro a Pesquisador (DPI) | C23: VGY01N0106N
A24: - Auxílio Financeiro a Pesquisador (DPG) | C24: VGY01N0106N

Sheet Estudo de Crédito
A1: Acompanhamento de Contratos*
A2: Data de Atualização: 14/10/2025
A3: Descrição das despesas | B3: UGR | C3: Prioridade | D3: PI 2025 | E3: CNPJ | F3: Processo | G3: Vigência | H3: Status do Contrato | I3: Situação da prorrogação | J3: nº Contrato | K3: Valor Contrato Média mensal | L3: Valor Cont Continuado Mensal | M3: Total estimado Anual | N3: Saldo Empenhos 2025 | O3: Saldo de Empenhos RAP | P3: Total RAP + Empenho | Q3: 45658 | R3: 45689 | S3: 45717 | T3: 45748 | U3: 45778 | V3: 45809 | W3: 45839 | X3: 45870 | Y3: 45901 | Z3: 45931 | AA3: 45962 | AB3: 45992 | AC3: Credito em Excesso
A4: - Estagiários UnB (novo PI - estagiários) | B4: DGP/ folha | C4: 1 | D4: VGM01N01N2N | K4: 161000 | M4: =K4*12 -> 1932000 | N4: 788950.31 | O4: 20575.19 | P4: =SUM(N4:O4) -> 809525.5 | AC4: =P4-(3*K4) -> 326525.5
A5: Estagiários - auxílio transporte | B5: DGP/ folha | C5: 1 | D5: VGM01N01N7N | K5: 36375 | N5: 234275.33 | O5: 7160.7 | P5: =SUM(N5:O5) -> 241436.03 | AC5: =P5-(3*K5) -> 132311.03
A6: SANEAGO - Água e esgoto UnB Cerrado (corrigir a média) | B6: UnB Cerrado | C6: 3 | D6: VGM01N01I3N | E6: 01616929000102 | K6: 333 | M6: =K6*12 -> 3996 | N6: 999 | O6: 1332 | P6: =SUM(N6:O6) -> 2331 | X6: 333 | AC6: 999 | AF6: =P6-AE6 -> 2331
A7: Energia Elétrica UnB Cerrado - CONTRATO CCER - ENEL N. 36/2020 e CELG DISTRIBUIÇÃO S.A - CELG D, Equatorial Goiás Distribuidora de Energia S/A | B7: UnB Cerrado | C7: 3 | D7: VGM01N01I2N | E7: 1543032000104 | F7: 23106.044802/2020-09 23106.083937/2023-24 | J7: 36/2020 | K7: 1585.03 | M7: =K7*12 -> 19020.36 | N7: =3635.35+1573.77 -> 5209.12 | O7: 145.87 | P7: =SUM(N7:O7) -> 5354.99 | V7: =K7-324 -> 1261.03 | X7: =1585-1230 -> 355 | AC7: =P7-(3*K7) -> 599.9 | AE7: =SUM(K7:L7)*2 -> 3170.06 | AF7: =P7-AE7 -> 2184.93 | AH7: =(SUM(K7:L7)*2)-P7 -> -2184.93
A8: Inframérica - Agenciamento de Carga Internacional (conforme demanda) | B8: Contratos DCO | C8: 2 | D8: VGM01N01L3N | E8: 15559082000186 | F8: 23106.011.137/2014-11 23106.086385/2019-20 | G8: 45743 | H8: =IF((G8-TODAY())<0,"EXPIRADO", IF((G8-TODAY())<=60,"EM BREVE","NO PRAZO")) -> EXPIRADO | J8: 026/2020 | N8: 0 | O8: 0 | P8: =SUM(N8:O8) -> 0 | AC8: =SUM(Z8:AB8) -> 0 | AE8: =SUM(K8:L8)*2 -> 0 | AF8: =P8-AE8 -> 0
A9: Inframérica - prestação de serviços de armazenagem e capatazia de cargas importadas (conforme demanda) | B9: Contratos DCO | D9: VGM01N01L3N | E9: 15.559.082/0001-86 | F9: 23106.010064/2025-01 | G9: 47682 | H9: =IF((G9-TODAY())<0,"EXPIRADO", IF((G9-TODAY())<=60,"EM BREVE","NO PRAZO")) -> NO PRAZO | J9: 1203/2025 | K9: 4000 | M9: =K9*12 -> 48000 | N9: 42484.67 | P9: =SUM(N9:O9) -> 42484.67 | AC9: =P9-(3*K9) -> 30484.67
A10: NK LOGISTICA E TRANSPORTES LTDA (serviços de transporte de cargas por via aérea) | B10: Contratos DCO | C10: 2 | D10: VGM01N01P2N | E10: 32270711000172 | F10: 23106.068904/2022-73 | G10: 45989 | H10: =IF((G10-TODAY())<0,"EXPIRADO", IF((G10-TODAY())<=60,"EM BREVE","NO PRAZO")) -> EM BREVE | I10: em renovação | J10: 130/2022 | K10: 500 | M10: =K10*12 -> 6000 | O10: 57249.08 | P10: =SUM(N10:O10) -> 57249.08
A11: - Seguro de aluno/ estagiário (MBM Seguradora S.A) | B11: Contratos DCO | C11: 1 | D11: VGM01N01N7N | E11: 87883807000106 | F11: 23106.085902/2019-43 | G11: 46086 | H11: =IF((G11-TODAY())<0,"EXPIRADO", IF((G11-TODAY())<=60,"EM BREVE","NO PRAZO")) -> NO PRAZO | J11: 024/2020 | K11: 3870 | M11: 48000 | N11: 22306.96 | O11: 0 | P11: =SUM(N11:O11) -> 22306.96 | AC11: =P11-(3*K11) -> 10696.96 | AE11: =SUM(K11:L11)*2 -> 7740
A12: PRIME EXTINTORES EIRELI – ME – recarga de extintores | B12: PRC | C12: 2 | D12: VGM01N01I6N | E12: 09.098.197/0001-18 | F12: 23106.101317/2023-84 | G12: 46137 | H12: =IF((G12-TODAY())<0,"EXPIRADO", IF((G12-TODAY())<=60,"EM BREVE","NO PRAZO")) -> NO PRAZO | J12: 618/2024 | K12: 10000 | M12: 187401.54 | N12: 100 | O12: 38595.64 | P12: =SUM(N12:O12) -> 38695.64 | AC12: 100 | AE12: =SUM(K12:L12)*2 -> 20000 | AF12: =P12-AE12 -> 18695.64
A13: - Fornecimento de combustível (Novo fornecer para 2019 - Ticket soluções HDFGT S/A) (NÃO DEVE SER ANULADO) | B13: PRC | C13: 3 | D13: VGM01N01I5N | E13: 3506307000157 | F13: 23106.116807/2021-13 | G13: 46270 | H13: =IF((G13-TODAY())<0,"EXPIRADO", IF((G13-TODAY())<=60,"EM BREVE","NO PRAZO")) -> NO PRAZO | I13: em renovação | J13: 1222/2022 | K13: 80000 | M13: =K13*12 -> 960000 | N13: 380000.32 | O13: 0 | P13: =SUM(N13:O13) -> 380000.32 | X13: =80000-12226 -> 67774 | AC13: =P13-(3*K13) -> 140000.32 | AE13: =SUM(K13:L13)*2 -> 160000 | AG13: =P13-AE13 -> 220000.32
A14: - Taxigov (demanda) - VIP service | B14: PRC | C14: 3 | D14: VGM01N01A4N | E14: 02605452000122 | F14: 23106.010532/2020-24 | G14: 46094 | H14: =IF((G14-TODAY())<0,"EXPIRADO", IF((G14-TODAY())<=60,"EM BREVE","NO PRAZO")) -> NO PRAZO | J14: 036/2020 | K14: 6000 | M14: =K14*12 -> 72000 | N14: 18000.52 | O14: 0 | P14: =SUM(N14:O14) -> 18000.52 | AC14: =P14-(3*K14) -> 0.52 | AE14: =SUM(K14:L14)*2 -> 12000 | AG14: -2000
A15: ELYON BRASIL - ESPLANADA SERVICOS TERCEIRIZADOS EIRELI - serviços continuados de pessoal - coletores de resíduos de serviços de saúde | B15: Contratos DCA | C15: 1 | D15: VGM01N01E4N | E15: 01099686000182 | F15: 23106.031888/2020-00 | G15: 46219 | H15: =IF((G15-TODAY())<0,"EXPIRADO", IF((G15-TODAY())<=60,"EM BREVE","NO PRAZO")) -> NO PRAZO | I15: Em fase de prorrogação | J15: 111/2020 | L15: =M15/12 -> 22669.34 | M15: 272032.08 | N15: 87845.52 | O15: 0 | P15: =SUM(N15:O15) -> 87845.52 | U15: =22669-1831.59 -> 20837.41 | X15: =L15-1000 -> 21669.34 | AC15: =P15-(3*L15) -> 19837.5 | AE15: =SUM(K15:L15)*2 -> 45338.68 | AF15: =P15-AE15 -> 42506.84 | AH15: =(SUM(K15:L15)*2)-P15 -> -42506.84
A16: - ALFA E OMEGA Apoio Técnico EDU | B16: Contratos DCA | C16: 1 | D16: VGM01N01D5N | E16: 16650774000106 | F16: 23106.011967/2019-52 | G16: 46131 | H16: =IF((G16-TODAY())<0,"EXPIRADO", IF((G16-TODAY())<=60,"EM BREVE","NO PRAZO")) -> NO PRAZO | J16: 022/2021 | L16: =M16/12 -> 24316.78 | M16: 291801.36 | N16: 100930.13 | O16: 0 | P16: =SUM(N16:O16) -> 100930.13 | S16: 865.66 | T16: =L16-2497 -> 21819.78 | U16: =L16-22360 -> 1956.78 | V16: =L16 -> 24316.78 | AC16: =P16-(3*L16) -> 27979.79 | AE16: =SUM(K16:L16)*2 -> 48633.56 | AF16: =P16-AE16 -> 52296.57 | AH16: =(SUM(K16:L16)*2)-P16 -> -52296.57
A17: Phoenix Comércio e Serviços de Limpeza LTDA - Almoxarifado e de transporte interno de móveis e materiais | B17: Contratos DCA | C17: 1 | D17: VGM01N01F7N | E17: 12978051000171 | F17: 23106.001099/2022-06 | G17: 46267 | H17: =IF((G17-TODAY())<0,"EXPIRADO", IF((G17-TODAY())<=60,"EM BREVE","NO PRAZO")) -> NO PRAZO | J17: 111/2022 | L17: 116248.37 | M17: =L17*12 -> 1394980.4 | N17: 509265.92 | O17: 0 | P17: =SUM(N17:O17) -> 509265.92 | T17: =117871-49371 -> 68500 | U17: =L17-P17 -> -393017.55 | V17: =L17 -> 116248.37 | AC17: =P17-(3*L17) -> 160520.81 | AE17: =SUM(K17:L17)*2 -> 232496.74 | AG17: -212997.86 | AH17: =(SUM(K17:L17)*2)-P17 -> -276769.18
A18: RB GRÁFICA DIGITAL LTDA | B18: Contratos DCA | C18: 2 | D18: VGM01N01Q1N | E18: 16.951.665/0001-10 | F18: 23106.041918/2022-40 | G18: 46266 | H18: =IF((G18-TODAY())<0,"EXPIRADO", IF((G18-TODAY())<=60,"EM BREVE","NO PRAZO")) -> NO PRAZO | J18: 104/2023 | K18: 100 | M18: =K18*12 -> 1200 | N18: 1200 | O18: 139 | P18: =SUM(N18:O18) -> 1339 | S18: =K18 -> 100 | AC18: =P18-(3*K18) -> 1039 | AE18: =SUM(K18:L18)*2 -> 200 | AH18: =(SUM(K18:L18)*2)-P18 -> -1139
A19: Contrato de Limpeza - UnB Cerrado (AP PISCINAS EIRELI) | B19: UnB Cerrado | C19: 1 | D19: VGM01N01A7N (VGM01N1F2N-PI indevido) | E19: 08475822000130 | F19: 23106.116355/2019-55 | G19: 46254 | H19: =IF((G19-TODAY())<0,"EXPIRADO", IF((G19-TODAY())<=60,"EM BREVE","NO PRAZO")) -> NO PRAZO | J19: 112/2020 | L19: 5954.2 | M19: 63975.84 | N19: 22887.42 | O19: 0 | P19: =SUM(N19:O19) -> 22887.42 | S19: =L19-P19 -> -16933.22 | T19: =L19-4688 -> 1266.2 | V19: =5331-P19 -> -17556.42 | W19: =L19-4396 -> 1558.2 | X19: =L19 -> 5954.2 | AC19: =P19-(3*L19) -> 5024.82 | AE19: =SUM(K19:L19)*2 -> 11908.4 | AG19: -643.35 | AH19: =(SUM(K19:L19)*2)-P19 -> -10979.02
A20: Recepcionista – AMR LIMPEZA E LOCACAO DE AUTOMOVEIS LTDA | B20: UnB Cerrado | C20: 1 | D20: VGM01N01B3N | E20: 10.258.826/0001-09 | F20: 23106.100112/2023-81 | G20: 46068 | H20: =IF((G20-TODAY())<0,"EXPIRADO", IF((G20-TODAY())<=60,"EM BREVE","NO PRAZO")) -> NO PRAZO | J20: 12/2024 | L20: =M20/12 -> 4290.91 | M20: 51490.92 | N20: =30036.37+4537.93 -> 34574.3 | O20: 0 | P20: =SUM(N20:O20) -> 34574.3 | V20: =L20 -> 4290.91 | AC20: =P20-(3*L20) -> 21701.57 | AE20: =SUM(K20:L20)*2 -> 8581.82 | AF20: =P20-AE20 -> 25992.48 | AH20: =(SUM(K20:L20)*2)-P20 -> -25992.48
A21: ONE ELEVADORES DF LTDA | B21: Contratos SPI | C21: 2 | D21: VGM01N01I7N | E21: 02.633.335/0001-72 | F21: 23106.077388/2024-30 | G21: 47436 | H21: =IF((G21-TODAY())<0,"EXPIRADO", IF((G21-TODAY())<=60,"EM BREVE","NO PRAZO")) -> NO PRAZO | J21: 94/2024 | K21: =M21/12 -> 339678 | M21: =20380680/5 -> 4076136 | O21: 2995835 | P21: =SUM(N21:O21) -> 2995835
A22: - ENERGIA ELÉTRICA - SPI | B22: Contratos SPI | C22: 3 | D22: VGM01N01I2N | E22: 07522669000192 | K22: 40000 | M22: =K22*12 -> 480000 | N22: 121270.9 | O22: 2965.4 | P22: =SUM(N22:O22) -> 124236.3 | T22: =40000-12743 -> 27257 | V22: =K22-23261 -> 16739 | AC22: =P22-(3*K22) -> 4236.3 | AE22: =K22*2 -> 80000 | AF22: =P22-AE22 -> 44236.3 | AH22: =(SUM(K22:L22)*2)-P22 -> -44236.3
A23: PGFN: 2° ATI, negociação conta n°: 8815031 (Consulta Acordo n°2 - Conta da Negociação 8815031 (SEI nº 10576277)) SEI origem: 23106.059565/2023-15 SEI pagamento 2023:23106.123083/2023-26 que foi realizado o pagamento da entrada e no 23106.128684/2023-25 constará os demais pagamentos. Despacho que contém explicação: 10567234 do SEI 23106.132563/2023-88 Guias de Recolhimento de FGTS e Informações à Previdência Social (GFIP) das competências de janeiro/2011, fevereiro/2011, abril/2011, junho/2011 e novembro/2011 Empenho atual: 2023NE003705; 2024NE000487 | B23: Contratos Diversos | C23: 2 | D23: VGH01N0112N | F23: 23106.059565/2023-15 23106.128684/2023-25 23106.044758/2024-52 23106.132563/2023-88 | G23: 60 parcelas (já pagou 10/60) | K23: 28500 | M23: =K23*12 -> 342000 | N23: =89029.91+28500 -> 117529.91 | O23: 0 | P23: =SUM(N23:O23) -> 117529.91 | V23: =28500-24893 -> 3607 | AH23: =(SUM(K23:L23)*2)-P23 -> -60529.91
A24: RFB: Conta da Negociação 0211000120 (Consulta Parcelamento n°1 - Conta da Negociação 0211000120 (SEI nº 10580261)) SEI origem: 23106.059634/2023-91 SEI pagamento em 2023: 23106.087581/2023-06 Despacho que contém explicação: 10567234 do SEI 23106.132563/2023-88 Atraso das Guias de Recolhimento de FGTS e Informações à Previdência Social (GFIP) das competências de julho/2010, outubro/2010, novembro/2010, dezembro/2011 e 13°/2011 Empenho atual: 2023NE003850 e 2024NE000284 | B24: Contratos Diversos | C24: 2 | D24: VGH01N0112N | F24: 23106.059634/2023-91 23106.087581/2023-06 23106.044758/2024-52 23106.132563/2023-88 | G24: 60 parcelas (já pagou 13/60) | K24: 22500 | M24: =K24*12 -> 270000 | N24: =45348.61+95199.17 -> 140547.78 | O24: 0 | P24: =SUM(N24:O24) -> 140547.78 | AH24: =(SUM(K24:L24)*2)-P24 -> -95547.78
A25: Contrato de serviços especializados com vistas à realização de estudos técnicos, de planejamentos, projetos básicos ou executivos, assessoria técnica e apoio técnico nas áreas de Tecnologia da Informação (TI) e Logística, entre a UnB e o CEBRASPE | B25: DEG | C25: 3 | D25: VGR02N01A2N | E25: 18284407000153 | F25: 23106.040707/2022-90 (60 parcelas) | G25: 46441 | H25: =IF((G25-TODAY())<0,"EXPIRADO", IF((G25-TODAY())<=60,"EM BREVE","NO PRAZO")) -> NO PRAZO | J25: 1205/2022 | K25: 44033.82 | M25: =K25*12 -> 528405.84 | N25: 496006.57 | O25: 0 | P25: =SUM(N25:O25) -> 496006.57 | AE25: =K25*2 -> 88067.64 | AG25: -88067.64 | AH25: =(SUM(K25:L25)*2)-P25 -> -407938.93
A26: Tratador de Piscinas CO e casa Oscar Niemayer - (AP Piscinas EIRELI) - em fase de renovação | B26: Contratos Diversos | C26: 1 | D26: VGM01N01E2N | E26: 08475822000130 | F26: 23106.013349/2019-47 | G26: 45844 | H26: =IF((G26-TODAY())<0,"EXPIRADO", IF((G26-TODAY())<=60,"EM BREVE","NO PRAZO")) -> EXPIRADO | I26: não será renovado | J26: 93/2020 | L26: =M26/12 -> 5039.3475 | M26: 60472.17 | N26: 23684.51 | O26: 0 | P26: =SUM(N26:O26) -> 23684.51 | U26: =L26-166.38 -> 4872.9675 | V26: =L26 -> 5039.3475 | X26: =L26-1512 -> 3527.3475 | AC26: =P26-(3*L26) -> 8566.4675 | AE26: =L26*2 -> 10078.695 | AH26: =(SUM(K26:L26)*2)-P26 -> -13605.815
A27: - Correios - ECT -reduziu porque não temos mais contrato de encomendas | B27: Comunicação | C27: 2 | D27: VGM01N01J1N | E27: 34028316000707 | F27: 23106.137850/2017-36; 23106.070712/2018-41 23106.015565/2023-11 | G27: 46792 | H27: =IF((G27-TODAY())<0,"EXPIRADO", IF((G27-TODAY())<=60,"EM BREVE","NO PRAZO")) -> NO PRAZO | J27: 1207/2023 | K27: 3000 | M27: =K27*12 -> 36000 | N27: 12275.32 | O27: 0 | P27: =SUM(N27:O27) -> 12275.32 | AC27: =P27-(3*K27) -> 3275.32 | AE27: =K27*2 -> 6000 | AG27: -642 | AH27: =(SUM(K27:L27)*2)-P27 -> -6275.32
A28: - Empresa Brasil de Comunicação (EBC) | B28: Comunicação | C28: 2 | D28: VGM01N01I9N | F28: 23106.048294/2020-20 | G28: 46001 | H28: =IF((G28-TODAY())<0,"EXPIRADO", IF((G28-TODAY())<=60,"EM BREVE","NO PRAZO")) -> EM BREVE | J28: 213/2020 | K28: 2000 | M28: =K28*12 -> 24000 | N28: 6307.04 | O28: 0 | P28: =SUM(N28:O28) -> 6307.04 | U28: =K28-307 -> 1693 | AC28: =P28-(3*K28) -> 307.04 | AE28: =K28*2 -> 4000 | AF28: =P28-AE28 -> 2307.04 | AH28: =(SUM(K28:L28)*2)-P28 -> -2307.04
A29: Lavanderia Cristal Serviços Expressos Ltda (higienização e passadoria de becas) | B29: Cerimonial | C29: 3 | D29: VGM01N01B9N | E29: 01319181000186 | F29: 23106.001918/2023-98 | G29: 46136 | H29: =IF((G29-TODAY())<0,"EXPIRADO", IF((G29-TODAY())<=60,"EM BREVE","NO PRAZO")) -> NO PRAZO | J29: Dispensa. Nº 10002/2023 | K29: 500 | M29: =K29*12 -> 6000 | N29: 13933.9 | O29: 548.5 | P29: =SUM(N29:O29) -> 14482.4 | AC29: =P29-(3*K29) -> 12982.4 | AE29: =K29*2 -> 1000 | AF29: =P29-AE29-O29 -> 12933.9
AH30: =(SUM(K30:L30)*3)-P30 -> 0
A31: Total da despesa | K31: =SUM(K4:K29) -> 783974.85 | L31: =SUM(L4:L29) -> 178518.95 | M31: =SUM(M4:M29) -> 11174913 | N31: =SUM(N4:N29) -> 3180585.4 | O31: =SUM(O4:O29) -> 3124546.4 | P31: =SUM(P4:P29) -> 6305131.8 | Q31: =SUM(Q4:Q29) -> 0 | R31: =SUM(R4:R29) -> 0 | ... AC31: =SUM(AC4:AC29) -> 907188.92 | AE31: =SUM(AE4:AE29) -> 739215.59 | AF31: =SUM(AF4:AF29) -> 203484.7 | AG31: =SUM(AG4:AG29) -> -84350.53 | AH31: =SUM(AH4:AH29) -> -1042309.1
AG33: =#REF! -> #REF!
AG34: -6000000
AG35: -1280820.9
AG37: =SUM(AG33:AG34) -> #REF!
AG38: =AG37+#REF! -> #REF!

Sheet Prog-09.10
A1: Programação de Despesas
A2: Data de Atualização: 09/10/2025
A3: Descrição das despesas | B3: UGR | C3: Prioridade | D3: PI 2025 | E3: CNPJ | F3: nº Contrato | G3: 45931 | H3: 45962 | I3: 45992 | J3: Total necessário
A4: Pasep - HUB | B4: HUB | C4: 1 | D4: VGM01N01N1N | I4: 35300.26 | J4: =SUM(G4:I4) -> 35300.26
A5: Pasep - UnB | B5: DGP/ folha | C5: 1 | D5: VGM01N01N1N | H5: 186771.65 | I5: 810000 | J5: =SUM(G5:I5) -> 996771.65
A6: OI SA recuperação judicial | B6: STI | C6: 3 | D6: VGM01N01I4N | E6: 76535764000143 | F6: 515/2021 | G6: 4223.61 | H6: 60000 | I6: 60000 | J6: =SUM(G6:I6) -> 124223.61
A7: WEGH Assessoria e Logística Internacional Ltda, Agenciamento de Transportes de Cargas Internacionais WeghLogística | B7: Contratos DCO | C7: 2 | D7: VGM01N01L3N | E7: 65494742000166 | F7: 142/2023 | G7: 2427.07 | H7: 4000 | I7: 4000 | J7: =SUM(G7:I7) -> 10427.07
A8: VILELA SERVIÇO DE PAISAGISMO, PARQUES E JARDINS LTDA (jardinagem) | B8: PRC | C8: 2 | D8: VGM01N01A5N | E8: 32.751.565/0001-05 | F8: 1217/2023 | H8: 286247.78 | I8: 298000 | J8: =SUM(G8:I8) -> 584247.78
A9: - TRANSMONICI TRANSPORTE E TURISMO (ônibus rodoviário executivo) | B9: PRC | C9: 2 | D9: VGM01N01K1N | E9: 09169349000126 | F9: 604/2022 | G9: 84327.88 | H9: 90000 | I9: 90000 | J9: =G9+H9+I9 -> 264327.88
A10: Tafa Engenharia (serviços continuados de manutenção preventiva e corretiva de equipamentos e sistemas de ar condicionado, com fornecimento de peças e materiais) | B10: PRC | C10: 2 | D10: VGM01N01F1N | E10: 12859652000165 | F10: 616/2024 | H10: 66316.59 | I10: 95000 | J10: =SUM(G10:I10) -> 161316.59
A11: 3P HGM solução visual (serviços de comunicação visual) | B11: PRC | C11: 2 | D11: VGM01N01O7N | E11: 34.998.513/0001-55 | F11: 1217/2022 | H11: 5228.16 | I11: 231000 | J11: =SUM(G11:I11) -> 236228.16
A12: ARTES GRÁFICA COMÉRCIO E REPRESENTAÇÕES EIRELI (serviços continuados de Designer Gráfico) | B12: Contratos DCA | C12: 2 | D12: VGM01N01P4N | E12: 05606994000108 | F12: 147/2022 | H12: 12640.77 | I12: 12640.77 | J12: =SUM(G12:I12) -> 25281.54
A13: OBJETIVA SERVIÇOS TERCEIRIZADOS LTDA - copeiragem | B13: Contratos DCA | D13: VGM01N01O2N | E13: 10.874.523/0001-10 | F13: 24/2025 | G13: 62.11 | H13: 155277.21 | I13: 155277.21 | J13: =SUM(G13:I13) -> 310616.53
A14: OBJETIVA SERVIÇOS TERCEIRIZADOS LTDA - contínuo | B14: Contratos DCA | D14: VGM01N01B7N | E14: 10.874.523/0001-10 | F14: 23/2025 | G14: 165.8 | H14: 258893.8 | I14: 258893.8 | J14: =SUM(G14:I14) -> 517953.4
